<?xml version="1.0" ?>
<robot name="gripper" xmlns:xacro="http://www.ros.org/wiki/xacro">

<xacro:include filename="$(find gripper_description)/urdf/materials.xacro" />
<xacro:include filename="$(find gripper_description)/urdf/gripper.trans" />
<xacro:include filename="$(find gripper_description)/urdf/gripper.gazebo" />
<link name="gripper_base_link">
  <inertial>
    <origin xyz="-0.06930330432389567 0.1480589720476463 -0.025544286170088252" rpy="0 0 0"/>
    <mass value="0.9719353305681612"/>
    <inertia ixx="0.00049" iyy="0.000557" izz="0.000578" ixy="-1e-06" iyz="-9e-06" ixz="0.000116"/>
  </inertial>
  <visual>
    <origin xyz="0 0 0" rpy="0 0 0"/>
    <geometry>
      <mesh filename="package://gripper_description/meshes/gripper_base_link.stl" scale="0.001 0.001 0.001"/>
    </geometry>
    <material name="silver"/>
  </visual>
  <collision>
    <origin xyz="0 0 0" rpy="0 0 0"/>
    <geometry>
      <mesh filename="package://gripper_description/meshes/gripper_base_link.stl" scale="0.001 0.001 0.001"/>
    </geometry>
  </collision>
</link>

<link name="link1">
  <inertial>
    <origin xyz="0.025240953749213958 0.02424613800333089 0.004999999999999901" rpy="0 0 0"/>
    <mass value="0.0851839232743157"/>
    <inertia ixx="2.8e-05" iyy="3e-05" izz="5.7e-05" ixy="-2.7e-05" iyz="-0.0" ixz="0.0"/>
  </inertial>
  <visual>
    <origin xyz="0.038971 -0.164837 0.0" rpy="0 0 0"/>
    <geometry>
      <mesh filename="package://gripper_description/meshes/link1.stl" scale="0.001 0.001 0.001"/>
    </geometry>
    <material name="silver"/>
  </visual>
  <collision>
    <origin xyz="0.038971 -0.164837 0.0" rpy="0 0 0"/>
    <geometry>
      <mesh filename="package://gripper_description/meshes/link1.stl" scale="0.001 0.001 0.001"/>
    </geometry>
  </collision>
</link>

<link name="link3">
  <inertial>
    <origin xyz="0.018230231416085364 -0.02987724109270805 0.004999999999999947" rpy="0 0 0"/>
    <mass value="0.08518393559594871"/>
    <inertia ixx="4.2e-05" iyy="1.7e-05" izz="5.7e-05" ixy="2.4e-05" iyz="0.0" ixz="0.0"/>
  </inertial>
  <visual>
    <origin xyz="0.038971 -0.128737 0.0" rpy="0 0 0"/>
    <geometry>
      <mesh filename="package://gripper_description/meshes/link3.stl" scale="0.001 0.001 0.001"/>
    </geometry>
    <material name="silver"/>
  </visual>
  <collision>
    <origin xyz="0.038971 -0.128737 0.0" rpy="0 0 0"/>
    <geometry>
      <mesh filename="package://gripper_description/meshes/link3.stl" scale="0.001 0.001 0.001"/>
    </geometry>
  </collision>
</link>

<link name="link2">
  <inertial>
    <origin xyz="0.02524079026132333 0.024246225707795138 0.004999999999999907" rpy="0 0 0"/>
    <mass value="0.06678651495220049"/>
    <inertia ixx="2e-05" iyy="2.2e-05" izz="4.1e-05" ixy="-2e-05" iyz="0.0" ixz="-0.0"/>
  </inertial>
  <visual>
    <origin xyz="0.014093 -0.154787 0.0" rpy="0 0 0"/>
    <geometry>
      <mesh filename="package://gripper_description/meshes/link2.stl" scale="0.001 0.001 0.001"/>
    </geometry>
    <material name="silver"/>
  </visual>
  <collision>
    <origin xyz="0.014093 -0.154787 0.0" rpy="0 0 0"/>
    <geometry>
      <mesh filename="package://gripper_description/meshes/link2.stl" scale="0.001 0.001 0.001"/>
    </geometry>
  </collision>
</link>

<link name="link4">
  <inertial>
    <origin xyz="0.018230065239373604 -0.029877294933871715 0.004999999999999914" rpy="0 0 0"/>
    <mass value="0.06678651495224165"/>
    <inertia ixx="3e-05" iyy="1.2e-05" izz="4.1e-05" ixy="1.8e-05" iyz="-0.0" ixz="-0.0"/>
  </inertial>
  <visual>
    <origin xyz="0.014093 -0.138787 0.0" rpy="0 0 0"/>
    <geometry>
      <mesh filename="package://gripper_description/meshes/link4.stl" scale="0.001 0.001 0.001"/>
    </geometry>
    <material name="silver"/>
  </visual>
  <collision>
    <origin xyz="0.014093 -0.138787 0.0" rpy="0 0 0"/>
    <geometry>
      <mesh filename="package://gripper_description/meshes/link4.stl" scale="0.001 0.001 0.001"/>
    </geometry>
  </collision>
</link>

<link name="link5">
  <inertial>
    <origin xyz="0.016772894969398076 -0.00818690525076679 0.004999999999999888" rpy="0 0 0"/>
    <mass value="0.050250119706585376"/>
    <inertia ixx="4e-06" iyy="1.2e-05" izz="1.5e-05" ixy="6e-06" iyz="-0.0" ixz="-0.0"/>
  </inertial>
  <visual>
    <origin xyz="-0.011511 -0.213329 -0.01" rpy="0 0 0"/>
    <geometry>
      <mesh filename="package://gripper_description/meshes/link5.stl" scale="0.001 0.001 0.001"/>
    </geometry>
    <material name="silver"/>
  </visual>
  <collision>
    <origin xyz="-0.011511 -0.213329 -0.01" rpy="0 0 0"/>
    <geometry>
      <mesh filename="package://gripper_description/meshes/link5.stl" scale="0.001 0.001 0.001"/>
    </geometry>
  </collision>
</link>

<link name="link5">
  <inertial>
    <origin xyz="0.013798894969398076 -0.01334890525076679 0.004999999999999888" rpy="0 0 0"/>
    <mass value="0.050250119706585376"/>
    <inertia ixx="4e-06" iyy="1.2e-05" izz="1.5e-05" ixy="6e-06" iyz="-0.0" ixz="-0.0"/>
  </inertial>
  <visual>
    <origin xyz="-0.014485 -0.218491 -0.01" rpy="0 0 0"/>
    <geometry>
      <mesh filename="package://gripper_description/meshes/link5.stl" scale="0.001 0.001 0.001"/>
    </geometry>
    <material name="silver"/>
  </visual>
  <collision>
    <origin xyz="-0.014485 -0.218491 -0.01" rpy="0 0 0"/>
    <geometry>
      <mesh filename="package://gripper_description/meshes/link5.stl" scale="0.001 0.001 0.001"/>
    </geometry>
  </collision>
</link>

<link name="link6">
  <inertial>
    <origin xyz="0.016772418745376695 0.008186864045676201 0.005000000001134073" rpy="0 0 0"/>
    <mass value="0.050250119235721834"/>
    <inertia ixx="4e-06" iyy="1.2e-05" izz="1.5e-05" ixy="-6e-06" iyz="-0.0" ixz="-0.0"/>
  </inertial>
  <visual>
    <origin xyz="0.00251 -0.068983 -0.01" rpy="0 0 0"/>
    <geometry>
      <mesh filename="package://gripper_description/meshes/link6.stl" scale="0.001 0.001 0.001"/>
    </geometry>
    <material name="silver"/>
  </visual>
  <collision>
    <origin xyz="0.00251 -0.068983 -0.01" rpy="0 0 0"/>
    <geometry>
      <mesh filename="package://gripper_description/meshes/link6.stl" scale="0.001 0.001 0.001"/>
    </geometry>
  </collision>
</link>

<link name="link6">
  <inertial>
    <origin xyz="-0.008105581254623302 -0.0018621359543238014 0.005000000001134073" rpy="0 0 0"/>
    <mass value="0.050250119235721834"/>
    <inertia ixx="4e-06" iyy="1.2e-05" izz="1.5e-05" ixy="-6e-06" iyz="-0.0" ixz="-0.0"/>
  </inertial>
  <visual>
    <origin xyz="-0.022368 -0.079032 -0.01" rpy="0 0 0"/>
    <geometry>
      <mesh filename="package://gripper_description/meshes/link6.stl" scale="0.001 0.001 0.001"/>
    </geometry>
    <material name="silver"/>
  </visual>
  <collision>
    <origin xyz="-0.022368 -0.079032 -0.01" rpy="0 0 0"/>
    <geometry>
      <mesh filename="package://gripper_description/meshes/link6.stl" scale="0.001 0.001 0.001"/>
    </geometry>
  </collision>
</link>

<link name="plate2">
  <inertial>
    <origin xyz="0.03765889407274898 -0.02538098094645444 -0.017000000000000397" rpy="0 0 0"/>
    <mass value="0.0928673984319522"/>
    <inertia ixx="1.2e-05" iyy="3.1e-05" izz="1.9e-05" ixy="0.0" iyz="-0.0" ixz="-0.0"/>
  </inertial>
  <visual>
    <origin xyz="-0.030604 -0.209596 -0.019" rpy="0 0 0"/>
    <geometry>
      <mesh filename="package://gripper_description/meshes/plate2.stl" scale="0.001 0.001 0.001"/>
    </geometry>
    <material name="silver"/>
  </visual>
  <collision>
    <origin xyz="-0.030604 -0.209596 -0.019" rpy="0 0 0"/>
    <geometry>
      <mesh filename="package://gripper_description/meshes/plate2.stl" scale="0.001 0.001 0.001"/>
    </geometry>
  </collision>
</link>

<link name="plate1">
  <inertial>
    <origin xyz="0.052262323030069044 0.03664491380276268 -0.018000000000000082" rpy="0 0 0"/>
    <mass value="0.09286739843195235"/>
    <inertia ixx="1.2e-05" iyy="3.1e-05" izz="1.9e-05" ixy="-0.0" iyz="0.0" ixz="-0.0"/>
  </inertial>
  <visual>
    <origin xyz="-0.003979 -0.061459 -0.02" rpy="0 0 0"/>
    <geometry>
      <mesh filename="package://gripper_description/meshes/plate1.stl" scale="0.001 0.001 0.001"/>
    </geometry>
    <material name="silver"/>
  </visual>
  <collision>
    <origin xyz="-0.003979 -0.061459 -0.02" rpy="0 0 0"/>
    <geometry>
      <mesh filename="package://gripper_description/meshes/plate1.stl" scale="0.001 0.001 0.001"/>
    </geometry>
  </collision>
</link>

<link name="link5_2">
  <inertial>
    <origin xyz="0.016772882317493503 -0.00818693116986946 -0.0050000000000001285" rpy="0 0 0"/>
    <mass value="0.050250119706585376"/>
    <inertia ixx="4e-06" iyy="1.2e-05" izz="1.5e-05" ixy="6e-06" iyz="-0.0" ixz="-0.0"/>
  </inertial>
  <visual>
    <origin xyz="-0.011511 -0.213329 0.0" rpy="0 0 0"/>
    <geometry>
      <mesh filename="package://gripper_description/meshes/link5_2.stl" scale="0.001 0.001 0.001"/>
    </geometry>
    <material name="silver"/>
  </visual>
  <collision>
    <origin xyz="-0.011511 -0.213329 0.0" rpy="0 0 0"/>
    <geometry>
      <mesh filename="package://gripper_description/meshes/link5_2.stl" scale="0.001 0.001 0.001"/>
    </geometry>
  </collision>
</link>

<link name="link5_2">
  <inertial>
    <origin xyz="0.013798882317493504 -0.01334893116986946 -0.0050000000000001285" rpy="0 0 0"/>
    <mass value="0.050250119706585376"/>
    <inertia ixx="4e-06" iyy="1.2e-05" izz="1.5e-05" ixy="6e-06" iyz="-0.0" ixz="-0.0"/>
  </inertial>
  <visual>
    <origin xyz="-0.014485 -0.218491 0.0" rpy="0 0 0"/>
    <geometry>
      <mesh filename="package://gripper_description/meshes/link5_2.stl" scale="0.001 0.001 0.001"/>
    </geometry>
    <material name="silver"/>
  </visual>
  <collision>
    <origin xyz="-0.014485 -0.218491 0.0" rpy="0 0 0"/>
    <geometry>
      <mesh filename="package://gripper_description/meshes/link5_2.stl" scale="0.001 0.001 0.001"/>
    </geometry>
  </collision>
</link>

<link name="component53_1">
  <inertial>
    <origin xyz="0.016772418745480168 0.008186864045702721 -0.004999999998866036" rpy="0 0 0"/>
    <mass value="0.0502501192354395"/>
    <inertia ixx="4e-06" iyy="1.2e-05" izz="1.5e-05" ixy="-6e-06" iyz="-0.0" ixz="-0.0"/>
  </inertial>
  <visual>
    <origin xyz="0.00251 -0.068983 0.0" rpy="0 0 0"/>
    <geometry>
      <mesh filename="package://gripper_description/meshes/component53_1.stl" scale="0.001 0.001 0.001"/>
    </geometry>
    <material name="silver"/>
  </visual>
  <collision>
    <origin xyz="0.00251 -0.068983 0.0" rpy="0 0 0"/>
    <geometry>
      <mesh filename="package://gripper_description/meshes/component53_1.stl" scale="0.001 0.001 0.001"/>
    </geometry>
  </collision>
</link>

<link name="component53_1">
  <inertial>
    <origin xyz="-0.00810558125451983 -0.001862135954297281 -0.004999999998866036" rpy="0 0 0"/>
    <mass value="0.0502501192354395"/>
    <inertia ixx="4e-06" iyy="1.2e-05" izz="1.5e-05" ixy="-6e-06" iyz="-0.0" ixz="-0.0"/>
  </inertial>
  <visual>
    <origin xyz="-0.022368 -0.079032 0.0" rpy="0 0 0"/>
    <geometry>
      <mesh filename="package://gripper_description/meshes/component53_1.stl" scale="0.001 0.001 0.001"/>
    </geometry>
    <material name="silver"/>
  </visual>
  <collision>
    <origin xyz="-0.022368 -0.079032 0.0" rpy="0 0 0"/>
    <geometry>
      <mesh filename="package://gripper_description/meshes/component53_1.stl" scale="0.001 0.001 0.001"/>
    </geometry>
  </collision>
</link>

<link name="Spur_Gear_36_teeth_1">
  <inertial>
    <origin xyz="-3.2714716231840857e-07 -4.718577417683889e-08 0.004999999999850697" rpy="0 0 0"/>
    <mass value="0.07732730680958116"/>
    <inertia ixx="7e-06" iyy="7e-06" izz="1.3e-05" ixy="-0.0" iyz="-0.0" ixz="-0.0"/>
  </inertial>
  <visual>
    <origin xyz="0.038971 -0.164837 -0.01" rpy="0 0 0"/>
    <geometry>
      <mesh filename="package://gripper_description/meshes/Spur_Gear_36_teeth_1.stl" scale="0.001 0.001 0.001"/>
    </geometry>
    <material name="silver"/>
  </visual>
  <collision>
    <origin xyz="0.038971 -0.164837 -0.01" rpy="0 0 0"/>
    <geometry>
      <mesh filename="package://gripper_description/meshes/Spur_Gear_36_teeth_1.stl" scale="0.001 0.001 0.001"/>
    </geometry>
  </collision>
</link>

<link name="Spur_Gear_36_teeth__1__1">
  <inertial>
    <origin xyz="-3.2694216475087634e-07 -5.104868550098729e-08 0.004999999999850752" rpy="0 0 0"/>
    <mass value="0.07732730680957652"/>
    <inertia ixx="7e-06" iyy="7e-06" izz="1.3e-05" ixy="-0.0" iyz="0.0" ixz="-0.0"/>
  </inertial>
  <visual>
    <origin xyz="0.038971 -0.128737 -0.01" rpy="0 0 0"/>
    <geometry>
      <mesh filename="package://gripper_description/meshes/Spur_Gear_36_teeth__1__1.stl" scale="0.001 0.001 0.001"/>
    </geometry>
    <material name="silver"/>
  </visual>
  <collision>
    <origin xyz="0.038971 -0.128737 -0.01" rpy="0 0 0"/>
    <geometry>
      <mesh filename="package://gripper_description/meshes/Spur_Gear_36_teeth__1__1.stl" scale="0.001 0.001 0.001"/>
    </geometry>
  </collision>
</link>

<link name="Spur_Gear_24_teeth__2__1">
  <inertial>
    <origin xyz="-7.93697714496222e-09 3.0987010735117337e-09 0.004999999999210494" rpy="0 0 0"/>
    <mass value="0.03267478605457942"/>
    <inertia ixx="2e-06" iyy="2e-06" izz="3e-06" ixy="0.0" iyz="0.0" ixz="0.0"/>
  </inertial>
  <visual>
    <origin xyz="0.068 -0.161 -0.01" rpy="0 0 0"/>
    <geometry>
      <mesh filename="package://gripper_description/meshes/Spur_Gear_24_teeth__2__1.stl" scale="0.001 0.001 0.001"/>
    </geometry>
    <material name="silver"/>
  </visual>
  <collision>
    <origin xyz="0.068 -0.161 -0.01" rpy="0 0 0"/>
    <geometry>
      <mesh filename="package://gripper_description/meshes/Spur_Gear_24_teeth__2__1.stl" scale="0.001 0.001 0.001"/>
    </geometry>
  </collision>
</link>

<link name="motor_adapter">
  <inertial>
    <origin xyz="-1.013170242147865e-09 2.399086901361258e-09 0.004944029318102771" rpy="0 0 0"/>
    <mass value="0.020408786210083112"/>
    <inertia ixx="1e-06" iyy="1e-06" izz="1e-06" ixy="0.0" iyz="0.0" ixz="-0.0"/>
  </inertial>
  <visual>
    <origin xyz="0.068 -0.161 -0.0" rpy="0 0 0"/>
    <geometry>
      <mesh filename="package://gripper_description/meshes/motor_adapter.stl" scale="0.001 0.001 0.001"/>
    </geometry>
    <material name="silver"/>
  </visual>
  <collision>
    <origin xyz="0.068 -0.161 -0.0" rpy="0 0 0"/>
    <geometry>
      <mesh filename="package://gripper_description/meshes/motor_adapter.stl" scale="0.001 0.001 0.001"/>
    </geometry>
  </collision>
</link>

<link name="top_plate">
  <inertial>
    <origin xyz="0.017426995133512174 -5.1303759518450676e-08 0.02155194345598499" rpy="0 0 0"/>
    <mass value="0.4820949144390761"/>
    <inertia ixx="0.00016" iyy="0.000149" izz="0.000203" ixy="0.0" iyz="-0.0" ixz="-2.3e-05"/>
  </inertial>
  <visual>
    <origin xyz="0.052321 -0.146787 0.036" rpy="0 0 0"/>
    <geometry>
      <mesh filename="package://gripper_description/meshes/top_plate.stl" scale="0.001 0.001 0.001"/>
    </geometry>
    <material name="silver"/>
  </visual>
  <collision>
    <origin xyz="0.052321 -0.146787 0.036" rpy="0 0 0"/>
    <geometry>
      <mesh filename="package://gripper_description/meshes/top_plate.stl" scale="0.001 0.001 0.001"/>
    </geometry>
  </collision>
</link>

<joint name="joint5" type="continuous">
  <origin xyz="0.01335 0.01805 0.036" rpy="0 0 0"/>
  <parent link="top_plate"/>
  <child link="link1"/>
  <axis xyz="-0.0 0.0 -1.0"/>
</joint>

<joint name="joint6" type="continuous">
  <origin xyz="0.01335 -0.01805 0.036" rpy="0 0 0"/>
  <parent link="top_plate"/>
  <child link="link3"/>
  <axis xyz="-0.0 0.0 -1.0"/>
</joint>

<joint name="joint7" type="continuous">
  <origin xyz="0.038228 0.008 0.036" rpy="0 0 0"/>
  <parent link="top_plate"/>
  <child link="link2"/>
  <axis xyz="-0.0 0.0 -1.0"/>
</joint>

<joint name="joint8" type="continuous">
  <origin xyz="0.038228 -0.008 0.036" rpy="0 0 0"/>
  <parent link="top_plate"/>
  <child link="link4"/>
  <axis xyz="-0.0 0.0 -1.0"/>
</joint>

<joint name="joint9" type="continuous">
  <origin xyz="0.053456 0.053654 0.01" rpy="0 0 0"/>
  <parent link="link1"/>
  <child link="link5"/>
  <axis xyz="-0.0 0.0 -1.0"/>
</joint>

<joint name="joint10" type="continuous">
  <origin xyz="0.028578 0.063704 0.01" rpy="0 0 0"/>
  <parent link="link2"/>
  <child link="link5"/>
  <axis xyz="-0.0 0.0 -1.0"/>
</joint>

<joint name="joint11" type="continuous">
  <origin xyz="0.061339 -0.049705 0.01" rpy="0 0 0"/>
  <parent link="link3"/>
  <child link="link6"/>
  <axis xyz="-0.0 0.0 -1.0"/>
</joint>

<joint name="joint12" type="continuous">
  <origin xyz="0.036461 -0.059755 0.01" rpy="0 0 0"/>
  <parent link="link4"/>
  <child link="link6"/>
  <axis xyz="-0.0 -0.0 -1.0"/>
</joint>

<joint name="fixed15" type="fixed">
  <origin xyz="0.016119 -0.008895 0.009" rpy="0 0 0"/>
  <parent link="link5"/>
  <child link="plate2"/>
</joint>

<joint name="fixed16" type="fixed">
  <origin xyz="-0.018389 -0.017573 0.01" rpy="0 0 0"/>
  <parent link="link6"/>
  <child link="plate1"/>
</joint>

<joint name="joint17" type="continuous">
  <origin xyz="0.053456 0.053654 0.0" rpy="0 0 0"/>
  <parent link="link1"/>
  <child link="link5_2"/>
  <axis xyz="0.0 0.0 1.0"/>
</joint>

<joint name="joint18" type="continuous">
  <origin xyz="0.028578 0.063704 0.0" rpy="0 0 0"/>
  <parent link="link2"/>
  <child link="link5_2"/>
  <axis xyz="0.0 -0.0 1.0"/>
</joint>

<joint name="joint19" type="continuous">
  <origin xyz="0.061339 -0.049705 0.0" rpy="0 0 0"/>
  <parent link="link3"/>
  <child link="component53_1"/>
  <axis xyz="0.0 -0.0 1.0"/>
</joint>

<joint name="joint20" type="continuous">
  <origin xyz="0.036461 -0.059755 0.0" rpy="0 0 0"/>
  <parent link="link4"/>
  <child link="component53_1"/>
  <axis xyz="-0.0 0.0 -1.0"/>
</joint>

<joint name="joint21" type="continuous">
  <origin xyz="0.0 0.0 0.01" rpy="0 0 0"/>
  <parent link="link1"/>
  <child link="Spur_Gear_36_teeth_1"/>
  <axis xyz="0.0 0.0 1.0"/>
</joint>

<joint name="joint22" type="continuous">
  <origin xyz="0.0 0.0 0.01" rpy="0 0 0"/>
  <parent link="link3"/>
  <child link="Spur_Gear_36_teeth__1__1"/>
  <axis xyz="-0.0 0.0 -1.0"/>
</joint>

<joint name="joint23" type="continuous">
  <origin xyz="0.0 0.0 0.01" rpy="0 0 0"/>
  <parent link="motor_adapter"/>
  <child link="Spur_Gear_24_teeth__2__1"/>
  <axis xyz="0.0 -0.0 -1.0"/>
</joint>

<joint name="fixed24" type="fixed">
  <origin xyz="-0.068 0.161 0.0" rpy="0 0 0"/>
  <parent link="gripper_base_link"/>
  <child link="motor_adapter"/>
</joint>

<joint name="fixed25" type="fixed">
  <origin xyz="-0.052321 0.146787 -0.036" rpy="0 0 0"/>
  <parent link="gripper_base_link"/>
  <child link="top_plate"/>
</joint>

</robot>
