<?xml version="1.0" ?>
<!-- URDF for robot_arm (extreme-robot 2025) -->
<robot xmlns:xacro="http://www.ros.org/wiki/xacro" name="robot_arm">
  <material name="silver">
    <color rgba="0.700 0.700 0.700 1.000"/>
  </material>
  <link name="base_link">
    <inertial>
      <origin xyz="-3.0231889621743065e-14 0.010000000000000446 -0.0025000000000000426" rpy="0 0 0"/>
      <mass value="0.7385873333015308"/>
      <inertia ixx="0.001446" iyy="0.001446" izz="0.00289" ixy="0.0" iyz="0.0" ixz="0.0"/>
    </inertial>
    <visual>
      <origin xyz="0 0 0" rpy="0 0 0"/>
      <geometry>
        <mesh filename="package://robot_arm_description/meshes/base_link.stl" scale="0.001 0.001 0.001"/>
      </geometry>
      <material name="silver"/>
    </visual>
    <collision>
      <origin xyz="0 0 0" rpy="0 0 0"/>
      <geometry>
        <mesh filename="package://robot_arm_description/meshes/base_link.stl" scale="0.001 0.001 0.001"/>
      </geometry>
    </collision>
  </link>
  <link name="Motor0_1">
    <inertial>
      <origin xyz="-3.863277416010047e-14 0.015028585409338708 0.02668166824738721" rpy="0 0 0"/>
      <mass value="0.664027798614862"/>
      <inertia ixx="0.000301" iyy="0.000169" izz="0.000249" ixy="-0.0" iyz="1e-06" ixz="-0.0"/>
    </inertial>
    <visual>
      <origin xyz="-0.0 -0.01 0.0045" rpy="0 0 0"/>
      <geometry>
        <mesh filename="package://robot_arm_description/meshes/Motor0_1.stl" scale="0.001 0.001 0.001"/>
      </geometry>
      <material name="silver"/>
    </visual>
    <collision>
      <origin xyz="-0.0 -0.01 0.0045" rpy="0 0 0"/>
      <geometry>
        <mesh filename="package://robot_arm_description/meshes/Motor0_1.stl" scale="0.001 0.001 0.001"/>
      </geometry>
    </collision>
  </link>
  <link name="Bottom_top_1">
    <inertial>
      <origin xyz="-1.7071321179720962e-15 1.9081958235744878e-17 0.0020000000000000018" rpy="0 0 0"/>
      <mass value="0.7527923586440036"/>
      <inertia ixx="0.001447" iyy="0.001447" izz="0.002891" ixy="0.0" iyz="0.0" ixz="0.0"/>
    </inertial>
    <visual>
      <origin xyz="-0.0 -0.01 -0.046" rpy="0 0 0"/>
      <geometry>
        <mesh filename="package://robot_arm_description/meshes/Bottom_top_1.stl" scale="0.001 0.001 0.001"/>
      </geometry>
      <material name="silver"/>
    </visual>
    <collision>
      <origin xyz="-0.0 -0.01 -0.046" rpy="0 0 0"/>
      <geometry>
        <mesh filename="package://robot_arm_description/meshes/Bottom_top_1.stl" scale="0.001 0.001 0.001"/>
      </geometry>
    </collision>
  </link>
  <link name="Bottom_Cylinder_1">
    <inertial>
      <origin xyz="1.1673433669600865e-16 8.500145032286355e-17 0.02324999999999998" rpy="0 0 0"/>
      <mass value="2.7522236601038736"/>
      <inertia ixx="0.00938" iyy="0.00938" izz="0.017769" ixy="0.0" iyz="0.0" ixz="0.0"/>
    </inertial>
    <visual>
      <origin xyz="-0.0 -0.01 0.0005" rpy="0 0 0"/>
      <geometry>
        <mesh filename="package://robot_arm_description/meshes/Bottom_Cylinder_1.stl" scale="0.001 0.001 0.001"/>
      </geometry>
      <material name="silver"/>
    </visual>
    <collision>
      <origin xyz="-0.0 -0.01 0.0005" rpy="0 0 0"/>
      <geometry>
        <mesh filename="package://robot_arm_description/meshes/Bottom_Cylinder_1.stl" scale="0.001 0.001 0.001"/>
      </geometry>
    </collision>
  </link>
  <link name="Link1_1">
    <inertial>
      <origin xyz="0.06415 -0.0020957372023369253 0.05901122254903374" rpy="0 0 0"/>
      <mass value="0.44759500853450696"/>
      <inertia ixx="0.001146" iyy="0.000539" izz="0.000608" ixy="0.0" iyz="2.7e-05" ixz="0.0"/>
    </inertial>
    <visual>
      <origin xyz="-0.0 -0.01 -0.05" rpy="0 0 0"/>
      <geometry>
        <mesh filename="package://robot_arm_description/meshes/Link1_1.stl" scale="0.001 0.001 0.001"/>
      </geometry>
      <material name="silver"/>
    </visual>
    <collision>
      <origin xyz="-0.0 -0.01 -0.05" rpy="0 0 0"/>
      <geometry>
        <mesh filename="package://robot_arm_description/meshes/Link1_1.stl" scale="0.001 0.001 0.001"/>
      </geometry>
    </collision>
  </link>
  <link name="Link1_1_1">
    <inertial>
      <origin xyz="-0.06415 -0.0017164543423660826 0.05888495455731886" rpy="0 0 0"/>
      <mass value="0.40614905152898423"/>
      <inertia ixx="0.001129" iyy="0.000531" izz="0.000599" ixy="-0.0" iyz="2.7e-05" ixz="-0.0"/>
    </inertial>
    <visual>
      <origin xyz="-0.0 -0.01 -0.05" rpy="0 0 0"/>
      <geometry>
        <mesh filename="package://robot_arm_description/meshes/Link1_1_1.stl" scale="0.001 0.001 0.001"/>
      </geometry>
      <material name="silver"/>
    </visual>
    <collision>
      <origin xyz="-0.0 -0.01 -0.05" rpy="0 0 0"/>
      <geometry>
        <mesh filename="package://robot_arm_description/meshes/Link1_1_1.stl" scale="0.001 0.001 0.001"/>
      </geometry>
    </collision>
  </link>
  <link name="Adapter_B_1">
    <inertial>
      <origin xyz="0.004824883876996186 -0.004186386606754951 -1.3877787807814457e-17" rpy="0 0 0"/>
      <mass value="0.0383693503096125"/>
      <inertia ixx="3e-06" iyy="3e-06" izz="3e-06" ixy="-0.0" iyz="0.0" ixz="-0.0"/>
    </inertial>
    <visual>
      <origin xyz="-0.06615 -0.008373 -0.11" rpy="0 0 0"/>
      <geometry>
        <mesh filename="package://robot_arm_description/meshes/Adapter_B_1.stl" scale="0.001 0.001 0.001"/>
      </geometry>
      <material name="silver"/>
    </visual>
    <collision>
      <origin xyz="-0.06615 -0.008373 -0.11" rpy="0 0 0"/>
      <geometry>
        <mesh filename="package://robot_arm_description/meshes/Adapter_B_1.stl" scale="0.001 0.001 0.001"/>
      </geometry>
    </collision>
  </link>
  <link name="Motor_1">
    <inertial>
      <origin xyz="-0.024181668247387128 -3.866067306334056e-07 -0.015028585409338782" rpy="0 0 0"/>
      <mass value="0.6640277986148609"/>
      <inertia ixx="0.000249" iyy="0.000301" izz="0.000169" ixy="0.0" iyz="0.0" ixz="1e-06"/>
    </inertial>
    <visual>
      <origin xyz="-0.06365 -0.004187 -0.11" rpy="0 0 0"/>
      <geometry>
        <mesh filename="package://robot_arm_description/meshes/Motor_1.stl" scale="0.001 0.001 0.001"/>
      </geometry>
      <material name="silver"/>
    </visual>
    <collision>
      <origin xyz="-0.06365 -0.004187 -0.11" rpy="0 0 0"/>
      <geometry>
        <mesh filename="package://robot_arm_description/meshes/Motor_1.stl" scale="0.001 0.001 0.001"/>
      </geometry>
    </collision>
  </link>
  <link name="Adapter_A_1">
    <inertial>
      <origin xyz="-0.009554439967386133 -3.866063680683929e-07 5.551115123125783e-17" rpy="0 0 0"/>
      <mass value="0.09838512042156757"/>
      <inertia ixx="1.5e-05" iyy="1.9e-05" izz="1.9e-05" ixy="0.0" iyz="0.0" ixz="0.0"/>
    </inertial>
    <visual>
      <origin xyz="-0.01565 -0.004187 -0.11" rpy="0 0 0"/>
      <geometry>
        <mesh filename="package://robot_arm_description/meshes/Adapter_A_1.stl" scale="0.001 0.001 0.001"/>
      </geometry>
      <material name="silver"/>
    </visual>
    <collision>
      <origin xyz="-0.01565 -0.004187 -0.11" rpy="0 0 0"/>
      <geometry>
        <mesh filename="package://robot_arm_description/meshes/Adapter_A_1.stl" scale="0.001 0.001 0.001"/>
      </geometry>
    </collision>
  </link>
  <link name="GearBox1_1">
    <inertial>
      <origin xyz="-0.037292278685380785 -0.004186386606694072 8.708984095898153e-06" rpy="0 0 0"/>
      <mass value="2.039024001006148"/>
      <inertia ixx="0.001172" iyy="0.001608" izz="0.001608" ixy="0.0" iyz="-0.0" ixz="1e-06"/>
    </inertial>
    <visual>
      <origin xyz="-0.00635 -0.008373 -0.11" rpy="0 0 0"/>
      <geometry>
        <mesh filename="package://robot_arm_description/meshes/GearBox1_1.stl" scale="0.001 0.001 0.001"/>
      </geometry>
      <material name="silver"/>
    </visual>
    <collision>
      <origin xyz="-0.00635 -0.008373 -0.11" rpy="0 0 0"/>
      <geometry>
        <mesh filename="package://robot_arm_description/meshes/GearBox1_1.stl" scale="0.001 0.001 0.001"/>
      </geometry>
    </collision>
  </link>
  <link name="Plug_1">
    <inertial>
      <origin xyz="0.012332017843283291 -3.866066470058563e-07 -9.570163065349135e-05" rpy="0 0 0"/>
      <mass value="0.1272431550006768"/>
      <inertia ixx="2.8e-05" iyy="2.3e-05" izz="2.3e-05" ixy="0.0" iyz="-0.0" ixz="-0.0"/>
    </inertial>
    <visual>
      <origin xyz="0.09815 -0.004187 -0.11" rpy="0 0 0"/>
      <geometry>
        <mesh filename="package://robot_arm_description/meshes/Plug_1.stl" scale="0.001 0.001 0.001"/>
      </geometry>
      <material name="silver"/>
    </visual>
    <collision>
      <origin xyz="0.09815 -0.004187 -0.11" rpy="0 0 0"/>
      <geometry>
        <mesh filename="package://robot_arm_description/meshes/Plug_1.stl" scale="0.001 0.001 0.001"/>
      </geometry>
    </collision>
  </link>
  <link name="Link2_1_1">
    <inertial>
      <origin xyz="0.0020000000000006263 0.14864650946057295 0.01004017457935627" rpy="0 0 0"/>
      <mass value="1.157660785545272"/>
      <inertia ixx="0.01443" iyy="0.001494" izz="0.012938" ixy="0.0" iyz="-0.001638" ixz="-0.0"/>
    </inertial>
    <visual>
      <origin xyz="0.08165 -0.004187 -0.11" rpy="0 0 0"/>
      <geometry>
        <mesh filename="package://robot_arm_description/meshes/Link2_1_1.stl" scale="0.001 0.001 0.001"/>
      </geometry>
      <material name="silver"/>
    </visual>
    <collision>
      <origin xyz="0.08165 -0.004187 -0.11" rpy="0 0 0"/>
      <geometry>
        <mesh filename="package://robot_arm_description/meshes/Link2_1_1.stl" scale="0.001 0.001 0.001"/>
      </geometry>
    </collision>
  </link>
  <link name="Link2Bridge_1">
    <inertial>
      <origin xyz="0.08130000000000007 2.1976118805278055e-07 0.001999998360872196" rpy="0 0 0"/>
      <mass value="0.45400523112316815"/>
      <inertia ixx="0.000318" iyy="0.000932" izz="0.001249" ixy="0.0" iyz="0.0" ixz="0.0"/>
    </inertial>
    <visual>
      <origin xyz="0.08165 -0.152338 -0.156" rpy="0 0 0"/>
      <geometry>
        <mesh filename="package://robot_arm_description/meshes/Link2Bridge_1.stl" scale="0.001 0.001 0.001"/>
      </geometry>
      <material name="silver"/>
    </visual>
    <collision>
      <origin xyz="0.08165 -0.152338 -0.156" rpy="0 0 0"/>
      <geometry>
        <mesh filename="package://robot_arm_description/meshes/Link2Bridge_1.stl" scale="0.001 0.001 0.001"/>
      </geometry>
    </collision>
  </link>
  <link name="Link2_1">
    <inertial>
      <origin xyz="-0.0020000000000000573 0.003975273937677604 -0.034235847349593965" rpy="0 0 0"/>
      <mass value="1.217857292535348"/>
      <inertia ixx="0.01582" iyy="0.001615" izz="0.014208" ixy="0.0" iyz="-0.001977" ixz="0.0"/>
    </inertial>
    <visual>
      <origin xyz="-0.08095 -0.152338 -0.156" rpy="0 0 0"/>
      <geometry>
        <mesh filename="package://robot_arm_description/meshes/Link2_1.stl" scale="0.001 0.001 0.001"/>
      </geometry>
      <material name="silver"/>
    </visual>
    <collision>
      <origin xyz="-0.08095 -0.152338 -0.156" rpy="0 0 0"/>
      <geometry>
        <mesh filename="package://robot_arm_description/meshes/Link2_1.stl" scale="0.001 0.001 0.001"/>
      </geometry>
    </collision>
  </link>
  <link name="Link2Bridge2_1">
    <inertial>
      <origin xyz="-0.08130000000000003 2.1976118780298037e-07 -0.002000001639127738" rpy="0 0 0"/>
      <mass value="0.6239106311231684"/>
      <inertia ixx="0.000834" iyy="0.00127" izz="0.002103" ixy="0.0" iyz="0.0" ixz="0.0"/>
    </inertial>
    <visual>
      <origin xyz="-0.08095 -0.169838 -0.064" rpy="0 0 0"/>
      <geometry>
        <mesh filename="package://robot_arm_description/meshes/Link2Bridge2_1.stl" scale="0.001 0.001 0.001"/>
      </geometry>
      <material name="silver"/>
    </visual>
    <collision>
      <origin xyz="-0.08095 -0.169838 -0.064" rpy="0 0 0"/>
      <geometry>
        <mesh filename="package://robot_arm_description/meshes/Link2Bridge2_1.stl" scale="0.001 0.001 0.001"/>
      </geometry>
    </collision>
  </link>
  <link name="Adapter_b_1_1">
    <inertial>
      <origin xyz="-0.00713943012326336 -3.866062500690326e-07 -1.6394831880983673e-09" rpy="0 0 0"/>
      <mass value="0.1507674746734739"/>
      <inertia ixx="1.5e-05" iyy="3.5e-05" izz="3.5e-05" ixy="-0.0" iyz="0.0" ixz="0.0"/>
    </inertial>
    <visual>
      <origin xyz="-0.07695 -0.297187 -0.17" rpy="0 0 0"/>
      <geometry>
        <mesh filename="package://robot_arm_description/meshes/Adapter_b_1_1.stl" scale="0.001 0.001 0.001"/>
      </geometry>
      <material name="silver"/>
    </visual>
    <collision>
      <origin xyz="-0.07695 -0.297187 -0.17" rpy="0 0 0"/>
      <geometry>
        <mesh filename="package://robot_arm_description/meshes/Adapter_b_1_1.stl" scale="0.001 0.001 0.001"/>
      </geometry>
    </collision>
  </link>
  <link name="Motor1_1">
    <inertial>
      <origin xyz="-0.02418166824738753 -3.8660673123969147e-07 -0.015028587048466963" rpy="0 0 0"/>
      <mass value="0.6640277986148614"/>
      <inertia ixx="0.000249" iyy="0.000301" izz="0.000169" ixy="0.0" iyz="0.0" ixz="1e-06"/>
    </inertial>
    <visual>
      <origin xyz="-0.04815 -0.297187 -0.17" rpy="0 0 0"/>
      <geometry>
        <mesh filename="package://robot_arm_description/meshes/Motor1_1.stl" scale="0.001 0.001 0.001"/>
      </geometry>
      <material name="silver"/>
    </visual>
    <collision>
      <origin xyz="-0.04815 -0.297187 -0.17" rpy="0 0 0"/>
      <geometry>
        <mesh filename="package://robot_arm_description/meshes/Motor1_1.stl" scale="0.001 0.001 0.001"/>
      </geometry>
    </collision>
  </link>
  <link name="Adapter_A_1_1">
    <inertial>
      <origin xyz="-0.009554439967386228 -3.866063680857401e-07 -1.6391278889749117e-09" rpy="0 0 0"/>
      <mass value="0.09838512042156751"/>
      <inertia ixx="1.5e-05" iyy="1.9e-05" izz="1.9e-05" ixy="0.0" iyz="0.0" ixz="-0.0"/>
    </inertial>
    <visual>
      <origin xyz="-0.00015 -0.297187 -0.17" rpy="0 0 0"/>
      <geometry>
        <mesh filename="package://robot_arm_description/meshes/Adapter_A_1_1.stl" scale="0.001 0.001 0.001"/>
      </geometry>
      <material name="silver"/>
    </visual>
    <collision>
      <origin xyz="-0.00015 -0.297187 -0.17" rpy="0 0 0"/>
      <geometry>
        <mesh filename="package://robot_arm_description/meshes/Adapter_A_1_1.stl" scale="0.001 0.001 0.001"/>
      </geometry>
    </collision>
  </link>
  <link name="GearBox2_1">
    <inertial>
      <origin xyz="-0.03715506640089916 -0.004186386606694181 -9.030635245488305e-06" rpy="0 0 0"/>
      <mass value="2.0338757908094958"/>
      <inertia ixx="0.001172" iyy="0.001592" izz="0.001592" ixy="0.0" iyz="0.0" ixz="-1e-06"/>
    </inertial>
    <visual>
      <origin xyz="0.00915 -0.301373 -0.17" rpy="0 0 0"/>
      <geometry>
        <mesh filename="package://robot_arm_description/meshes/GearBox2_1.stl" scale="0.001 0.001 0.001"/>
      </geometry>
      <material name="silver"/>
    </visual>
    <collision>
      <origin xyz="0.00915 -0.301373 -0.17" rpy="0 0 0"/>
      <geometry>
        <mesh filename="package://robot_arm_description/meshes/GearBox2_1.stl" scale="0.001 0.001 0.001"/>
      </geometry>
    </collision>
  </link>
  <link name="_Plug2_1">
    <inertial>
      <origin xyz="0.012332017843283347 -3.8660664769540887e-07 -9.570326978175503e-05" rpy="0 0 0"/>
      <mass value="0.12724315500067693"/>
      <inertia ixx="2.8e-05" iyy="2.3e-05" izz="2.3e-05" ixy="0.0" iyz="-0.0" ixz="-0.0"/>
    </inertial>
    <visual>
      <origin xyz="0.11365 -0.297187 -0.17" rpy="0 0 0"/>
      <geometry>
        <mesh filename="package://robot_arm_description/meshes/_Plug2_1.stl" scale="0.001 0.001 0.001"/>
      </geometry>
      <material name="silver"/>
    </visual>
    <collision>
      <origin xyz="0.11365 -0.297187 -0.17" rpy="0 0 0"/>
      <geometry>
        <mesh filename="package://robot_arm_description/meshes/_Plug2_1.stl" scale="0.001 0.001 0.001"/>
      </geometry>
    </collision>
  </link>
  <link name="Link3_1">
    <inertial>
      <origin xyz="0.001999999999999849 -0.07474132737436856 0.04314461050419041" rpy="0 0 0"/>
      <mass value="0.8074135897799332"/>
      <inertia ixx="0.004928" iyy="0.001217" izz="0.003713" ixy="0.0" iyz="0.001001" ixz="0.0"/>
    </inertial>
    <visual>
      <origin xyz="0.09715 -0.297187 -0.17" rpy="0 0 0"/>
      <geometry>
        <mesh filename="package://robot_arm_description/meshes/Link3_1.stl" scale="0.001 0.001 0.001"/>
      </geometry>
      <material name="silver"/>
    </visual>
    <collision>
      <origin xyz="0.09715 -0.297187 -0.17" rpy="0 0 0"/>
      <geometry>
        <mesh filename="package://robot_arm_description/meshes/Link3_1.stl" scale="0.001 0.001 0.001"/>
      </geometry>
    </collision>
  </link>
  <link name="Link3Bridge_1">
    <inertial>
      <origin xyz="0.09714999999999986 -3.551512779975674e-07 0.001999996721744224" rpy="0 0 0"/>
      <mass value="0.6617159687507393"/>
      <inertia ixx="0.000687" iyy="0.001953" izz="0.002639" ixy="-0.0" iyz="-0.0" ixz="-0.0"/>
    </inertial>
    <visual>
      <origin xyz="0.09715 -0.190447 -0.276" rpy="0 0 0"/>
      <geometry>
        <mesh filename="package://robot_arm_description/meshes/Link3Bridge_1.stl" scale="0.001 0.001 0.001"/>
      </geometry>
      <material name="silver"/>
    </visual>
    <collision>
      <origin xyz="0.09715 -0.190447 -0.276" rpy="0 0 0"/>
      <geometry>
        <mesh filename="package://robot_arm_description/meshes/Link3Bridge_1.stl" scale="0.001 0.001 0.001"/>
      </geometry>
    </collision>
  </link>
  <link name="Link3_1_1">
    <inertial>
      <origin xyz="-0.002000000000000071 0.033379133168915665 -0.06364769393241707" rpy="0 0 0"/>
      <mass value="0.8226070917771181"/>
      <inertia ixx="0.005043" iyy="0.001247" izz="0.003798" ixy="0.0" iyz="0.001049" ixz="-0.0"/>
    </inertial>
    <visual>
      <origin xyz="-0.09715 -0.190447 -0.276" rpy="0 0 0"/>
      <geometry>
        <mesh filename="package://robot_arm_description/meshes/Link3_1_1.stl" scale="0.001 0.001 0.001"/>
      </geometry>
      <material name="silver"/>
    </visual>
    <collision>
      <origin xyz="-0.09715 -0.190447 -0.276" rpy="0 0 0"/>
      <geometry>
        <mesh filename="package://robot_arm_description/meshes/Link3_1_1.stl" scale="0.001 0.001 0.001"/>
      </geometry>
    </collision>
  </link>
  <link name="Link3Bridge2_1">
    <inertial>
      <origin xyz="-0.09715000000000001 -0.018239436351202593 -0.002000003278255641" rpy="0 0 0"/>
      <mass value="0.44527262875074014"/>
      <inertia ixx="0.000209" iyy="0.001327" izz="0.001535" ixy="-0.0" iyz="0.0" ixz="0.0"/>
    </inertial>
    <visual>
      <origin xyz="-0.09715 -0.190447 -0.184" rpy="0 0 0"/>
      <geometry>
        <mesh filename="package://robot_arm_description/meshes/Link3Bridge2_1.stl" scale="0.001 0.001 0.001"/>
      </geometry>
      <material name="silver"/>
    </visual>
    <collision>
      <origin xyz="-0.09715 -0.190447 -0.184" rpy="0 0 0"/>
      <geometry>
        <mesh filename="package://robot_arm_description/meshes/Link3Bridge2_1.stl" scale="0.001 0.001 0.001"/>
      </geometry>
    </collision>
  </link>
  <link name="Link4_1">
    <inertial>
      <origin xyz="0.037724999999999724 -0.0020004249962814052 -3.278255722438672e-09" rpy="0 0 0"/>
      <mass value="0.21556100000000022"/>
      <inertia ixx="0.00018" iyy="0.000265" izz="8.5e-05" ixy="-0.0" iyz="0.0" ixz="-0.0"/>
    </inertial>
    <visual>
      <origin xyz="0.09715 -0.10256 -0.23" rpy="0 0 0"/>
      <geometry>
        <mesh filename="package://robot_arm_description/meshes/Link4_1.stl" scale="0.001 0.001 0.001"/>
      </geometry>
      <material name="silver"/>
    </visual>
    <collision>
      <origin xyz="0.09715 -0.10256 -0.23" rpy="0 0 0"/>
      <geometry>
        <mesh filename="package://robot_arm_description/meshes/Link4_1.stl" scale="0.001 0.001 0.001"/>
      </geometry>
    </collision>
  </link>
  <link name="Link_5_1">
    <inertial>
      <origin xyz="0.0019999999999994675 -0.056021662888809255 -0.0020213120388476447" rpy="0 0 0"/>
      <mass value="0.3236352008265773"/>
      <inertia ixx="0.000571" iyy="0.000258" izz="0.000313" ixy="0.0" iyz="-2.9e-05" ixz="0.0"/>
    </inertial>
    <visual>
      <origin xyz="0.0285 -0.10256 -0.23" rpy="0 0 0"/>
      <geometry>
        <mesh filename="package://robot_arm_description/meshes/Link_5_1.stl" scale="0.001 0.001 0.001"/>
      </geometry>
      <material name="silver"/>
    </visual>
    <collision>
      <origin xyz="0.0285 -0.10256 -0.23" rpy="0 0 0"/>
      <geometry>
        <mesh filename="package://robot_arm_description/meshes/Link_5_1.stl" scale="0.001 0.001 0.001"/>
      </geometry>
    </collision>
  </link>
  <link name="Motor2_1">
    <inertial>
      <origin xyz="0.02131833175261221 -3.8660673124663036e-07 -0.015028588687594713" rpy="0 0 0"/>
      <mass value="0.6640277986148616"/>
      <inertia ixx="0.000249" iyy="0.000301" izz="0.000169" ixy="0.0" iyz="0.0" ixz="1e-06"/>
    </inertial>
    <visual>
      <origin xyz="0.0245 -0.039187 -0.23" rpy="0 0 0"/>
      <geometry>
        <mesh filename="package://robot_arm_description/meshes/Motor2_1.stl" scale="0.001 0.001 0.001"/>
      </geometry>
      <material name="silver"/>
    </visual>
    <collision>
      <origin xyz="0.0245 -0.039187 -0.23" rpy="0 0 0"/>
      <geometry>
        <mesh filename="package://robot_arm_description/meshes/Motor2_1.stl" scale="0.001 0.001 0.001"/>
      </geometry>
    </collision>
  </link>
  <link name="Adapter_B_1_1_1">
    <inertial>
      <origin xyz="0.006611236997704481 -3.8660681661584206e-07 -3.278255722438672e-09" rpy="0 0 0"/>
      <mass value="0.0836288961017048"/>
      <inertia ixx="1.4e-05" iyy="9e-06" izz="9e-06" ixy="0.0" iyz="0.0" ixz="0.0"/>
    </inertial>
    <visual>
      <origin xyz="-0.021 -0.039187 -0.23" rpy="0 0 0"/>
      <geometry>
        <mesh filename="package://robot_arm_description/meshes/Adapter_B_1_1_1.stl" scale="0.001 0.001 0.001"/>
      </geometry>
      <material name="silver"/>
    </visual>
    <collision>
      <origin xyz="-0.021 -0.039187 -0.23" rpy="0 0 0"/>
      <geometry>
        <mesh filename="package://robot_arm_description/meshes/Adapter_B_1_1_1.stl" scale="0.001 0.001 0.001"/>
      </geometry>
    </collision>
  </link>
  <link name="Link5_1_1">
    <inertial>
      <origin xyz="-0.002000000000000321 0.003928241492784798 -0.002231067651165153" rpy="0 0 0"/>
      <mass value="0.29320833347967973"/>
      <inertia ixx="0.000562" iyy="0.000255" izz="0.000308" ixy="0.0" iyz="-3e-05" ixz="0.0"/>
    </inertial>
    <visual>
      <origin xyz="-0.0284 -0.043373 -0.23" rpy="0 0 0"/>
      <geometry>
        <mesh filename="package://robot_arm_description/meshes/Link5_1_1.stl" scale="0.001 0.001 0.001"/>
      </geometry>
      <material name="silver"/>
    </visual>
    <collision>
      <origin xyz="-0.0284 -0.043373 -0.23" rpy="0 0 0"/>
      <geometry>
        <mesh filename="package://robot_arm_description/meshes/Link5_1_1.stl" scale="0.001 0.001 0.001"/>
      </geometry>
    </collision>
  </link>
  <link name="Link4_1_1">
    <inertial>
      <origin xyz="0.030924999999999668 -0.0020004249962812665 -3.278255805705399e-09" rpy="0 0 0"/>
      <mass value="0.21556100000000022"/>
      <inertia ixx="0.00018" iyy="0.000265" izz="8.5e-05" ixy="0.0" iyz="0.0" ixz="0.0"/>
    </inertial>
    <visual>
      <origin xyz="-0.0284 -0.10256 -0.23" rpy="0 0 0"/>
      <geometry>
        <mesh filename="package://robot_arm_description/meshes/Link4_1_1.stl" scale="0.001 0.001 0.001"/>
      </geometry>
      <material name="silver"/>
    </visual>
    <collision>
      <origin xyz="-0.0284 -0.10256 -0.23" rpy="0 0 0"/>
      <geometry>
        <mesh filename="package://robot_arm_description/meshes/Link4_1_1.stl" scale="0.001 0.001 0.001"/>
      </geometry>
    </collision>
  </link>
  <joint name="Rigid 5" type="fixed">
    <origin xyz="0.0 0.01 -0.0045" rpy="0 0 0"/>
    <parent link="base_link"/>
    <child link="Motor0_1"/>
  </joint>
  <joint name="joint_1" type="continuous">
    <origin xyz="0.0 0.0 0.0505" rpy="0 0 0"/>
    <parent link="Motor0_1"/>
    <child link="Bottom_top_1"/>
    <axis xyz="0.0 0.0 1.0"/>
  </joint>
  <joint name="Rigid 21" type="fixed">
    <origin xyz="0.0 0.01 -0.0005" rpy="0 0 0"/>
    <parent link="base_link"/>
    <child link="Bottom_Cylinder_1"/>
  </joint>
  <joint name="Rigid 22" type="fixed">
    <origin xyz="0.0 0.0 0.004" rpy="0 0 0"/>
    <parent link="Bottom_top_1"/>
    <child link="Link1_1"/>
  </joint>
  <joint name="Rigid 23" type="fixed">
    <origin xyz="0.0 0.0 0.004" rpy="0 0 0"/>
    <parent link="Bottom_top_1"/>
    <child link="Link1_1_1"/>
  </joint>
  <joint name="Rigid 42" type="fixed">
    <origin xyz="0.06615 -0.001627 0.06" rpy="0 0 0"/>
    <parent link="Link1_1"/>
    <child link="Adapter_B_1"/>
  </joint>
  <joint name="Rigid 43" type="fixed">
    <origin xyz="-0.0025 -0.004186 0.0" rpy="0 0 0"/>
    <parent link="Adapter_B_1"/>
    <child link="Motor_1"/>
  </joint>
  <joint name="joint_2" type="revolute">
    <origin xyz="-0.048 0.0 0.0" rpy="0 0 0"/>
    <parent link="Motor_1"/>
    <child link="Adapter_A_1"/>
    <axis xyz="-1.0 -0.0 0.0"/>
    <limit upper="0.0" lower="-3.141593" effort="100" velocity="100"/>
  </joint>
  <joint name="Rigid 45" type="fixed">
    <origin xyz="-0.0093 0.004186 0.0" rpy="0 0 0"/>
    <parent link="Adapter_A_1"/>
    <child link="GearBox1_1"/>
  </joint>
  <joint name="Rigid 46" type="fixed">
    <origin xyz="-0.1045 -0.004186 0.0" rpy="0 0 0"/>
    <parent link="GearBox1_1"/>
    <child link="Plug_1"/>
  </joint>
  <joint name="Rigid 47" type="fixed">
    <origin xyz="0.0165 0.0 0.0" rpy="0 0 0"/>
    <parent link="Plug_1"/>
    <child link="Link2_1_1"/>
  </joint>
  <joint name="Rigid 48" type="fixed">
    <origin xyz="0.0 0.148151 0.046" rpy="0 0 0"/>
    <parent link="Link2_1_1"/>
    <child link="Link2Bridge_1"/>
  </joint>
  <joint name="Rigid 49" type="fixed">
    <origin xyz="0.1626 0.0 0.0" rpy="0 0 0"/>
    <parent link="Link2Bridge_1"/>
    <child link="Link2_1"/>
  </joint>
  <joint name="Rigid 50" type="fixed">
    <origin xyz="0.0 0.0175 -0.092" rpy="0 0 0"/>
    <parent link="Link2_1"/>
    <child link="Link2Bridge2_1"/>
  </joint>
  <joint name="Rigid 51" type="fixed">
    <origin xyz="-0.004 0.144849 0.014" rpy="0 0 0"/>
    <parent link="Link2_1"/>
    <child link="Adapter_b_1_1"/>
  </joint>
  <joint name="Rigid 52" type="fixed">
    <origin xyz="-0.0288 0.0 0.0" rpy="0 0 0"/>
    <parent link="Adapter_b_1_1"/>
    <child link="Motor1_1"/>
  </joint>
  <joint name="joint_3" type="revolute">
    <origin xyz="-0.048 0.0 0.0" rpy="0 0 0"/>
    <parent link="Motor1_1"/>
    <child link="Adapter_A_1_1"/>
    <axis xyz="-1.0 0.0 0.0"/>
    <limit upper="3.665191" lower="0.0" effort="100" velocity="100"/>
  </joint>
  <joint name="Rigid 54" type="fixed">
    <origin xyz="-0.0093 0.004186 0.0" rpy="0 0 0"/>
    <parent link="Adapter_A_1_1"/>
    <child link="GearBox2_1"/>
  </joint>
  <joint name="Rigid 55" type="fixed">
    <origin xyz="-0.1045 -0.004186 0.0" rpy="0 0 0"/>
    <parent link="GearBox2_1"/>
    <child link="_Plug2_1"/>
  </joint>
  <joint name="Rigid 56" type="fixed">
    <origin xyz="0.0165 0.0 0.0" rpy="0 0 0"/>
    <parent link="_Plug2_1"/>
    <child link="Link3_1"/>
  </joint>
  <joint name="Rigid 57" type="fixed">
    <origin xyz="0.0 -0.10674 0.106" rpy="0 0 0"/>
    <parent link="Link3_1"/>
    <child link="Link3Bridge_1"/>
  </joint>
  <joint name="Rigid 58" type="fixed">
    <origin xyz="0.1943 0.0 0.0" rpy="0 0 0"/>
    <parent link="Link3Bridge_1"/>
    <child link="Link3_1_1"/>
  </joint>
  <joint name="Rigid 59" type="fixed">
    <origin xyz="0.0 0.0 -0.092" rpy="0 0 0"/>
    <parent link="Link3_1_1"/>
    <child link="Link3Bridge2_1"/>
  </joint>
  <joint name="Rigid 60" type="fixed">
    <origin xyz="0.0 -0.194627 0.06" rpy="0 0 0"/>
    <parent link="Link3_1"/>
    <child link="Link4_1"/>
  </joint>
  <joint name="Rigid 61" type="fixed">
    <origin xyz="0.06865 0.0 0.0" rpy="0 0 0"/>
    <parent link="Link4_1"/>
    <child link="Link_5_1"/>
  </joint>
  <joint name="Rigid 62" type="fixed">
    <origin xyz="0.004 -0.063373 0.0" rpy="0 0 0"/>
    <parent link="Link_5_1"/>
    <child link="Motor2_1"/>
  </joint>
  <joint name="Rigid 63" type="fixed">
    <origin xyz="0.0455 0.0 0.0" rpy="0 0 0"/>
    <parent link="Motor2_1"/>
    <child link="Adapter_B_1_1_1"/>
  </joint>
  <joint name="Rigid 64" type="fixed">
    <origin xyz="0.0074 0.004186 0.0" rpy="0 0 0"/>
    <parent link="Adapter_B_1_1_1"/>
    <child link="Link5_1_1"/>
  </joint>
  <joint name="Rigid 65" type="fixed">
    <origin xyz="0.0 0.059187 0.0" rpy="0 0 0"/>
    <parent link="Link5_1_1"/>
    <child link="Link4_1_1"/>
  </joint>
</robot>
