<?xml version="1.0" ?>
<!-- URDF for robot_arm (extreme-robot 2025) - 2026-07-07 CAD export, 5-DOF -->
<robot xmlns:xacro="http://www.ros.org/wiki/xacro" name="robot_arm">
  <material name="silver">
    <color rgba="0.700 0.700 0.700 1.000"/>
  </material>
  <transmission name="joint_1_tran">
    <type>transmission_interface/SimpleTransmission</type>
    <joint name="joint_1">
      <hardwareInterface>hardware_interface/EffortJointInterface</hardwareInterface>
    </joint>
    <actuator name="joint_1_actr">
      <hardwareInterface>hardware_interface/EffortJointInterface</hardwareInterface>
      <mechanicalReduction>1</mechanicalReduction>
    </actuator>
  </transmission>
  <transmission name="joint_2_tran">
    <type>transmission_interface/SimpleTransmission</type>
    <joint name="joint_2">
      <hardwareInterface>hardware_interface/EffortJointInterface</hardwareInterface>
    </joint>
    <actuator name="joint_2_actr">
      <hardwareInterface>hardware_interface/EffortJointInterface</hardwareInterface>
      <mechanicalReduction>1</mechanicalReduction>
    </actuator>
  </transmission>
  <transmission name="joint_3_tran">
    <type>transmission_interface/SimpleTransmission</type>
    <joint name="joint_3">
      <hardwareInterface>hardware_interface/EffortJointInterface</hardwareInterface>
    </joint>
    <actuator name="joint_3_actr">
      <hardwareInterface>hardware_interface/EffortJointInterface</hardwareInterface>
      <mechanicalReduction>1</mechanicalReduction>
    </actuator>
  </transmission>
  <transmission name="joint_4_tran">
    <type>transmission_interface/SimpleTransmission</type>
    <joint name="joint_4">
      <hardwareInterface>hardware_interface/EffortJointInterface</hardwareInterface>
    </joint>
    <actuator name="joint_4_actr">
      <hardwareInterface>hardware_interface/EffortJointInterface</hardwareInterface>
      <mechanicalReduction>1</mechanicalReduction>
    </actuator>
  </transmission>
  <transmission name="joint_5_tran">
    <type>transmission_interface/SimpleTransmission</type>
    <joint name="joint_5">
      <hardwareInterface>hardware_interface/EffortJointInterface</hardwareInterface>
    </joint>
    <actuator name="joint_5_actr">
      <hardwareInterface>hardware_interface/EffortJointInterface</hardwareInterface>
      <mechanicalReduction>1</mechanicalReduction>
    </actuator>
  </transmission>
  <gazebo>
    <plugin name="control" filename="libgazebo_ros_control.so"/>
  </gazebo>
  <gazebo reference="base_link">
    <material>Gazebo/Silver</material>
    <mu1>0.2</mu1>
    <mu2>0.2</mu2>
    <selfCollide>true</selfCollide>
    <gravity>true</gravity>
  </gazebo>
  <gazebo reference="motor0_1">
    <material>Gazebo/Silver</material>
    <mu1>0.2</mu1>
    <mu2>0.2</mu2>
    <selfCollide>true</selfCollide>
  </gazebo>
  <gazebo reference="lower_cylinder_1">
    <material>Gazebo/Silver</material>
    <mu1>0.2</mu1>
    <mu2>0.2</mu2>
    <selfCollide>true</selfCollide>
  </gazebo>
  <gazebo reference="powertrain_1">
    <material>Gazebo/Silver</material>
    <mu1>0.2</mu1>
    <mu2>0.2</mu2>
    <selfCollide>true</selfCollide>
  </gazebo>
  <gazebo reference="base_plate_1">
    <material>Gazebo/Silver</material>
    <mu1>0.2</mu1>
    <mu2>0.2</mu2>
    <selfCollide>true</selfCollide>
  </gazebo>
  <gazebo reference="link1-1_1">
    <material>Gazebo/Silver</material>
    <mu1>0.2</mu1>
    <mu2>0.2</mu2>
    <selfCollide>true</selfCollide>
  </gazebo>
  <gazebo reference="link1_1">
    <material>Gazebo/Silver</material>
    <mu1>0.2</mu1>
    <mu2>0.2</mu2>
    <selfCollide>true</selfCollide>
  </gazebo>
  <gazebo reference="gearbox1_1">
    <material>Gazebo/Silver</material>
    <mu1>0.2</mu1>
    <mu2>0.2</mu2>
    <selfCollide>true</selfCollide>
  </gazebo>
  <gazebo reference="adapter_a_1">
    <material>Gazebo/Silver</material>
    <mu1>0.2</mu1>
    <mu2>0.2</mu2>
    <selfCollide>true</selfCollide>
  </gazebo>
  <gazebo reference="motor_1">
    <material>Gazebo/Silver</material>
    <mu1>0.2</mu1>
    <mu2>0.2</mu2>
    <selfCollide>true</selfCollide>
  </gazebo>
  <gazebo reference="adapter_b_1">
    <material>Gazebo/Silver</material>
    <mu1>0.2</mu1>
    <mu2>0.2</mu2>
    <selfCollide>true</selfCollide>
  </gazebo>
  <gazebo reference="Component40_1">
    <material>Gazebo/Silver</material>
    <mu1>0.2</mu1>
    <mu2>0.2</mu2>
    <selfCollide>true</selfCollide>
  </gazebo>
  <gazebo reference="link2_1">
    <material>Gazebo/Silver</material>
    <mu1>0.2</mu1>
    <mu2>0.2</mu2>
    <selfCollide>true</selfCollide>
  </gazebo>
  <gazebo reference="adapter_b__1__1">
    <material>Gazebo/Silver</material>
    <mu1>0.2</mu1>
    <mu2>0.2</mu2>
    <selfCollide>true</selfCollide>
  </gazebo>
  <gazebo reference="link2_leg2_1">
    <material>Gazebo/Silver</material>
    <mu1>0.2</mu1>
    <mu2>0.2</mu2>
    <selfCollide>true</selfCollide>
  </gazebo>
  <gazebo reference="link2_leg_1">
    <material>Gazebo/Silver</material>
    <mu1>0.2</mu1>
    <mu2>0.2</mu2>
    <selfCollide>true</selfCollide>
  </gazebo>
  <gazebo reference="Component38_1">
    <material>Gazebo/Silver</material>
    <mu1>0.2</mu1>
    <mu2>0.2</mu2>
    <selfCollide>true</selfCollide>
  </gazebo>
  <gazebo reference="link2-1__3__1">
    <material>Gazebo/Silver</material>
    <mu1>0.2</mu1>
    <mu2>0.2</mu2>
    <selfCollide>true</selfCollide>
  </gazebo>
  <gazebo reference="cap_1">
    <material>Gazebo/Silver</material>
    <mu1>0.2</mu1>
    <mu2>0.2</mu2>
    <selfCollide>true</selfCollide>
  </gazebo>
  <gazebo reference="motor1_1">
    <material>Gazebo/Silver</material>
    <mu1>0.2</mu1>
    <mu2>0.2</mu2>
    <selfCollide>true</selfCollide>
  </gazebo>
  <gazebo reference="adapter_a__1__1">
    <material>Gazebo/Silver</material>
    <mu1>0.2</mu1>
    <mu2>0.2</mu2>
    <selfCollide>true</selfCollide>
  </gazebo>
  <gazebo reference="gearbox1__1__1">
    <material>Gazebo/Silver</material>
    <mu1>0.2</mu1>
    <mu2>0.2</mu2>
    <selfCollide>true</selfCollide>
  </gazebo>
  <gazebo reference="cap2_1">
    <material>Gazebo/Silver</material>
    <mu1>0.2</mu1>
    <mu2>0.2</mu2>
    <selfCollide>true</selfCollide>
  </gazebo>
  <gazebo reference="link3_1">
    <material>Gazebo/Silver</material>
    <mu1>0.2</mu1>
    <mu2>0.2</mu2>
    <selfCollide>true</selfCollide>
  </gazebo>
  <gazebo reference="link3_leg_1">
    <material>Gazebo/Silver</material>
    <mu1>0.2</mu1>
    <mu2>0.2</mu2>
    <selfCollide>true</selfCollide>
  </gazebo>
  <gazebo reference="link3_leg2_1">
    <material>Gazebo/Silver</material>
    <mu1>0.2</mu1>
    <mu2>0.2</mu2>
    <selfCollide>true</selfCollide>
  </gazebo>
  <gazebo reference="link4_1">
    <material>Gazebo/Silver</material>
    <mu1>0.2</mu1>
    <mu2>0.2</mu2>
    <selfCollide>true</selfCollide>
  </gazebo>
  <gazebo reference="link5_1">
    <material>Gazebo/Silver</material>
    <mu1>0.2</mu1>
    <mu2>0.2</mu2>
    <selfCollide>true</selfCollide>
  </gazebo>
  <gazebo reference="adapter_1">
    <material>Gazebo/Silver</material>
    <mu1>0.2</mu1>
    <mu2>0.2</mu2>
    <selfCollide>true</selfCollide>
  </gazebo>
  <gazebo reference="motor2_1">
    <material>Gazebo/Silver</material>
    <mu1>0.2</mu1>
    <mu2>0.2</mu2>
    <selfCollide>true</selfCollide>
  </gazebo>
  <gazebo reference="link2__1__1">
    <material>Gazebo/Silver</material>
    <mu1>0.2</mu1>
    <mu2>0.2</mu2>
    <selfCollide>true</selfCollide>
  </gazebo>
  <gazebo reference="top_1">
    <material>Gazebo/Silver</material>
    <mu1>0.2</mu1>
    <mu2>0.2</mu2>
    <selfCollide>true</selfCollide>
  </gazebo>
  <gazebo reference="bottom_1">
    <material>Gazebo/Silver</material>
    <mu1>0.2</mu1>
    <mu2>0.2</mu2>
    <selfCollide>true</selfCollide>
  </gazebo>
  <gazebo reference="link3-1_1">
    <material>Gazebo/Silver</material>
    <mu1>0.2</mu1>
    <mu2>0.2</mu2>
    <selfCollide>true</selfCollide>
  </gazebo>
  <gazebo reference="link4-1_1">
    <material>Gazebo/Silver</material>
    <mu1>0.2</mu1>
    <mu2>0.2</mu2>
    <selfCollide>true</selfCollide>
  </gazebo>
  <gazebo reference="link5-1_1">
    <material>Gazebo/Silver</material>
    <mu1>0.2</mu1>
    <mu2>0.2</mu2>
    <selfCollide>true</selfCollide>
  </gazebo>
  <gazebo reference="adapter_b__1___1__1">
    <material>Gazebo/Silver</material>
    <mu1>0.2</mu1>
    <mu2>0.2</mu2>
    <selfCollide>true</selfCollide>
  </gazebo>
  <gazebo reference="link1__1__1">
    <material>Gazebo/Silver</material>
    <mu1>0.2</mu1>
    <mu2>0.2</mu2>
    <selfCollide>true</selfCollide>
  </gazebo>
  <gazebo reference="XL430_T_1">
    <material>Gazebo/Silver</material>
    <mu1>0.2</mu1>
    <mu2>0.2</mu2>
    <selfCollide>true</selfCollide>
  </gazebo>
  <gazebo reference="connector_1__1">
    <material>Gazebo/Silver</material>
    <mu1>0.2</mu1>
    <mu2>0.2</mu2>
    <selfCollide>true</selfCollide>
  </gazebo>
  <gazebo reference="module_connector_5axis_Component41_1">
    <material>Gazebo/Silver</material>
    <mu1>0.2</mu1>
    <mu2>0.2</mu2>
    <selfCollide>true</selfCollide>
  </gazebo>
  <link name="base_link">
    <inertial>
      <origin xyz="-3.0231889621743065e-14 4.463096558993129e-16 0.001999999999999958" rpy="0 0 0"/>
      <mass value="0.7385873333015308"/>
      <inertia ixx="0.001446" iyy="0.001446" izz="0.00289" ixy="0.0" iyz="0.0" ixz="0.0"/>
    </inertial>
    <visual>
      <origin xyz="0 0 0" rpy="0 0 0"/>
      <geometry>
        <mesh filename="package://robot_arm_description/meshes/base_link.stl" scale="0.001 0.001 0.001"/>
      </geometry>
      <material name="silver"/>
    </visual>
    <collision>
      <origin xyz="0 0 0" rpy="0 0 0"/>
      <geometry>
        <mesh filename="package://robot_arm_description/meshes/base_link.stl" scale="0.001 0.001 0.001"/>
      </geometry>
    </collision>
  </link>
  <link name="motor0_1">
    <inertial>
      <origin xyz="-3.8597247023312466e-14 0.015028585409338699 0.022681668247387224" rpy="0 0 0"/>
      <mass value="0.664027798614862"/>
      <inertia ixx="0.000301" iyy="0.000169" izz="0.000249" ixy="-0.0" iyz="1e-06" ixz="-0.0"/>
    </inertial>
    <visual>
      <origin xyz="-0.0 -0.0 -0.004" rpy="0 0 0"/>
      <geometry>
        <mesh filename="package://robot_arm_description/meshes/motor0_1.stl" scale="0.001 0.001 0.001"/>
      </geometry>
      <material name="silver"/>
    </visual>
    <collision>
      <origin xyz="-0.0 -0.0 -0.004" rpy="0 0 0"/>
      <geometry>
        <mesh filename="package://robot_arm_description/meshes/motor0_1.stl" scale="0.001 0.001 0.001"/>
      </geometry>
    </collision>
  </link>
  <link name="lower_cylinder_1">
    <inertial>
      <origin xyz="1.5241181618526498e-16 8.43769498715119e-17 0.023249999999999986" rpy="0 0 0"/>
      <mass value="2.7522236601038736"/>
      <inertia ixx="0.00938" iyy="0.00938" izz="0.017769" ixy="0.0" iyz="0.0" ixz="0.0"/>
    </inertial>
    <visual>
      <origin xyz="-0.0 -0.0 -0.004" rpy="0 0 0"/>
      <geometry>
        <mesh filename="package://robot_arm_description/meshes/lower_cylinder_1.stl" scale="0.001 0.001 0.001"/>
      </geometry>
      <material name="silver"/>
    </visual>
    <collision>
      <origin xyz="-0.0 -0.0 -0.004" rpy="0 0 0"/>
      <geometry>
        <mesh filename="package://robot_arm_description/meshes/lower_cylinder_1.stl" scale="0.001 0.001 0.001"/>
      </geometry>
    </collision>
  </link>
  <link name="powertrain_1">
    <inertial>
      <origin xyz="5.229102198782807e-13 -7.771561172376097e-18 0.0020000000000000157" rpy="0 0 0"/>
      <mass value="0.0024661502330680955"/>
      <inertia ixx="0.0" iyy="0.0" izz="0.0" ixy="-0.0" iyz="-0.0" ixz="-0.0"/>
    </inertial>
    <visual>
      <origin xyz="-0.0 -0.0 -0.0505" rpy="0 0 0"/>
      <geometry>
        <mesh filename="package://robot_arm_description/meshes/powertrain_1.stl" scale="0.001 0.001 0.001"/>
      </geometry>
      <material name="silver"/>
    </visual>
    <collision>
      <origin xyz="-0.0 -0.0 -0.0505" rpy="0 0 0"/>
      <geometry>
        <mesh filename="package://robot_arm_description/meshes/powertrain_1.stl" scale="0.001 0.001 0.001"/>
      </geometry>
    </collision>
  </link>
  <link name="base_plate_1">
    <inertial>
      <origin xyz="-1.6357771589935833e-15 1.5543122344752193e-17 0.0020000000000000226" rpy="0 0 0"/>
      <mass value="0.7527923586440036"/>
      <inertia ixx="0.001447" iyy="0.001447" izz="0.002891" ixy="0.0" iyz="0.0" ixz="0.0"/>
    </inertial>
    <visual>
      <origin xyz="-0.0 -0.0 -0.0505" rpy="0 0 0"/>
      <geometry>
        <mesh filename="package://robot_arm_description/meshes/base_plate_1.stl" scale="0.001 0.001 0.001"/>
      </geometry>
      <material name="silver"/>
    </visual>
    <collision>
      <origin xyz="-0.0 -0.0 -0.0505" rpy="0 0 0"/>
      <geometry>
        <mesh filename="package://robot_arm_description/meshes/base_plate_1.stl" scale="0.001 0.001 0.001"/>
      </geometry>
    </collision>
  </link>
  <link name="link1-1_1">
    <inertial>
      <origin xyz="-0.06414999999999992 0.008283545657633916 0.0543849545573189" rpy="0 0 0"/>
      <mass value="0.40614905152898423"/>
      <inertia ixx="0.001129" iyy="0.000531" izz="0.000599" ixy="-0.0" iyz="2.7e-05" ixz="-0.0"/>
    </inertial>
    <visual>
      <origin xyz="-0.0 0.01 -0.059" rpy="0 0 0"/>
      <geometry>
        <mesh filename="package://robot_arm_description/meshes/link1-1_1.stl" scale="0.001 0.001 0.001"/>
      </geometry>
      <material name="silver"/>
    </visual>
    <collision>
      <origin xyz="-0.0 0.01 -0.059" rpy="0 0 0"/>
      <geometry>
        <mesh filename="package://robot_arm_description/meshes/link1-1_1.stl" scale="0.001 0.001 0.001"/>
      </geometry>
    </collision>
  </link>
  <link name="link1_1">
    <inertial>
      <origin xyz="0.06415000000000005 0.00790426279766307 0.054511222549033775" rpy="0 0 0"/>
      <mass value="0.44759500853450696"/>
      <inertia ixx="0.001146" iyy="0.000539" izz="0.000608" ixy="0.0" iyz="2.7e-05" ixz="0.0"/>
    </inertial>
    <visual>
      <origin xyz="-0.0 0.01 -0.059" rpy="0 0 0"/>
      <geometry>
        <mesh filename="package://robot_arm_description/meshes/link1_1.stl" scale="0.001 0.001 0.001"/>
      </geometry>
      <material name="silver"/>
    </visual>
    <collision>
      <origin xyz="-0.0 0.01 -0.059" rpy="0 0 0"/>
      <geometry>
        <mesh filename="package://robot_arm_description/meshes/link1_1.stl" scale="0.001 0.001 0.001"/>
      </geometry>
    </collision>
  </link>
  <link name="gearbox1_1">
    <inertial>
      <origin xyz="0.03120772131461931 -0.00018694098015631377 -0.004491289376776342" rpy="0 0 0"/>
      <mass value="2.039024001006148"/>
      <inertia ixx="0.001172" iyy="0.001608" izz="0.001608" ixy="0.0" iyz="-0.0" ixz="1e-06"/>
    </inertial>
    <visual>
      <origin xyz="0.06215 0.005357 -0.119" rpy="0 0 0"/>
      <geometry>
        <mesh filename="package://robot_arm_description/meshes/gearbox1_1.stl" scale="0.001 0.001 0.001"/>
      </geometry>
      <material name="silver"/>
    </visual>
    <collision>
      <origin xyz="0.06215 0.005357 -0.119" rpy="0 0 0"/>
      <geometry>
        <mesh filename="package://robot_arm_description/meshes/gearbox1_1.stl" scale="0.001 0.001 0.001"/>
      </geometry>
    </collision>
  </link>
  <link name="adapter_a_1">
    <inertial>
      <origin xyz="0.0007455600326139681 0.005544059020169665 -0.0044999983608721705" rpy="0 0 0"/>
      <mass value="0.09838512042156757"/>
      <inertia ixx="1.5e-05" iyy="1.9e-05" izz="1.9e-05" ixy="0.0" iyz="-0.0" ixz="0.0"/>
    </inertial>
    <visual>
      <origin xyz="-0.00535 0.011088 -0.119" rpy="0 0 0"/>
      <geometry>
        <mesh filename="package://robot_arm_description/meshes/adapter_a_1.stl" scale="0.001 0.001 0.001"/>
      </geometry>
      <material name="silver"/>
    </visual>
    <collision>
      <origin xyz="-0.00535 0.011088 -0.119" rpy="0 0 0"/>
      <geometry>
        <mesh filename="package://robot_arm_description/meshes/adapter_a_1.stl" scale="0.001 0.001 0.001"/>
      </geometry>
    </collision>
  </link>
  <link name="motor_1">
    <inertial>
      <origin xyz="0.02381833175261278 5.901980715088129e-08 -0.015028583770211101" rpy="0 0 0"/>
      <mass value="0.6640277986148609"/>
      <inertia ixx="0.000249" iyy="0.000301" izz="0.000169" ixy="0.0" iyz="0.0" ixz="1e-06"/>
    </inertial>
    <visual>
      <origin xyz="-0.01565 0.005544 -0.1145" rpy="0 0 0"/>
      <geometry>
        <mesh filename="package://robot_arm_description/meshes/motor_1.stl" scale="0.001 0.001 0.001"/>
      </geometry>
      <material name="silver"/>
    </visual>
    <collision>
      <origin xyz="-0.01565 0.005544 -0.1145" rpy="0 0 0"/>
      <geometry>
        <mesh filename="package://robot_arm_description/meshes/motor_1.stl" scale="0.001 0.001 0.001"/>
      </geometry>
    </collision>
  </link>
  <link name="adapter_b_1">
    <inertial>
      <origin xyz="0.0088248838769963 5.901978278235326e-08 1.6391277363192458e-09" rpy="0 0 0"/>
      <mass value="0.0383693503096125"/>
      <inertia ixx="3e-06" iyy="3e-06" izz="3e-06" ixy="-0.0" iyz="0.0" ixz="-0.0"/>
    </inertial>
    <visual>
      <origin xyz="-0.06215 0.005544 -0.1145" rpy="0 0 0"/>
      <geometry>
        <mesh filename="package://robot_arm_description/meshes/adapter_b_1.stl" scale="0.001 0.001 0.001"/>
      </geometry>
      <material name="silver"/>
    </visual>
    <collision>
      <origin xyz="-0.06215 0.005544 -0.1145" rpy="0 0 0"/>
      <geometry>
        <mesh filename="package://robot_arm_description/meshes/adapter_b_1.stl" scale="0.001 0.001 0.001"/>
      </geometry>
    </collision>
  </link>
  <link name="Component40_1">
    <inertial>
      <origin xyz="0.002153890695419103 0.0585307168403934 2.4052570807661655e-05" rpy="0 0 0"/>
      <mass value="0.6121227780764895"/>
      <inertia ixx="0.002458" iyy="0.000468" izz="0.001993" ixy="-9e-06" iyz="-2e-06" ixz="-0.0"/>
    </inertial>
    <visual>
      <origin xyz="-0.07695 0.005544 -0.1145" rpy="0 0 0"/>
      <geometry>
        <mesh filename="package://robot_arm_description/meshes/Component40_1.stl" scale="0.001 0.001 0.001"/>
      </geometry>
      <material name="silver"/>
    </visual>
    <collision>
      <origin xyz="-0.07695 0.005544 -0.1145" rpy="0 0 0"/>
      <geometry>
        <mesh filename="package://robot_arm_description/meshes/Component40_1.stl" scale="0.001 0.001 0.001"/>
      </geometry>
    </collision>
  </link>
  <link name="link2_1">
    <inertial>
      <origin xyz="5.551115123125783e-17 0.0954484162795333 0.02952068914117935" rpy="0 0 0"/>
      <mass value="0.5760752094127702"/>
      <inertia ixx="0.002327" iyy="0.000769" izz="0.00156" ixy="-0.0" iyz="-0.00058" ixz="-0.0"/>
    </inertial>
    <visual>
      <origin xyz="-0.07895 -0.144456 -0.1135" rpy="0 0 0"/>
      <geometry>
        <mesh filename="package://robot_arm_description/meshes/link2_1.stl" scale="0.001 0.001 0.001"/>
      </geometry>
      <material name="silver"/>
    </visual>
    <collision>
      <origin xyz="-0.07895 -0.144456 -0.1135" rpy="0 0 0"/>
      <geometry>
        <mesh filename="package://robot_arm_description/meshes/link2_1.stl" scale="0.001 0.001 0.001"/>
      </geometry>
    </collision>
  </link>
  <link name="adapter_b__1__1">
    <inertial>
      <origin xyz="-0.007139430123263221 5.9020287879185673e-08 1.638772451073578e-09" rpy="0 0 0"/>
      <mass value="0.1507674746734739"/>
      <inertia ixx="1.5e-05" iyy="3.5e-05" izz="3.5e-05" ixy="-0.0" iyz="0.0" ixz="0.0"/>
    </inertial>
    <visual>
      <origin xyz="-0.07695 -0.287456 -0.1745" rpy="0 0 0"/>
      <geometry>
        <mesh filename="package://robot_arm_description/meshes/adapter_b__1__1.stl" scale="0.001 0.001 0.001"/>
      </geometry>
      <material name="silver"/>
    </visual>
    <collision>
      <origin xyz="-0.07695 -0.287456 -0.1745" rpy="0 0 0"/>
      <geometry>
        <mesh filename="package://robot_arm_description/meshes/adapter_b__1__1.stl" scale="0.001 0.001 0.001"/>
      </geometry>
    </collision>
  </link>
  <link name="link2_leg2_1">
    <inertial>
      <origin xyz="-0.0813 -0.025686581741381914 -0.0009999983608722507" rpy="0 0 0"/>
      <mass value="0.17597826669199707"/>
      <inertia ixx="7.6e-05" iyy="0.000362" izz="0.000437" ixy="0.0" iyz="-0.0" ixz="0.0"/>
    </inertial>
    <visual>
      <origin xyz="-0.08095 -0.158275 -0.0665" rpy="0 0 0"/>
      <geometry>
        <mesh filename="package://robot_arm_description/meshes/link2_leg2_1.stl" scale="0.001 0.001 0.001"/>
      </geometry>
      <material name="silver"/>
    </visual>
    <collision>
      <origin xyz="-0.08095 -0.158275 -0.0665" rpy="0 0 0"/>
      <geometry>
        <mesh filename="package://robot_arm_description/meshes/link2_leg2_1.stl" scale="0.001 0.001 0.001"/>
      </geometry>
    </collision>
  </link>
  <link name="link2_leg_1">
    <inertial>
      <origin xyz="-0.0793 0.012499665387725706 1.6391277501970336e-09" rpy="0 0 0"/>
      <mass value="0.22700261556158713"/>
      <inertia ixx="0.000159" iyy="0.000466" izz="0.000624" ixy="-0.0" iyz="0.0" ixz="-0.0"/>
    </inertial>
    <visual>
      <origin xyz="-0.07895 -0.130108 -0.1635" rpy="0 0 0"/>
      <geometry>
        <mesh filename="package://robot_arm_description/meshes/link2_leg_1.stl" scale="0.001 0.001 0.001"/>
      </geometry>
      <material name="silver"/>
    </visual>
    <collision>
      <origin xyz="-0.07895 -0.130108 -0.1635" rpy="0 0 0"/>
      <geometry>
        <mesh filename="package://robot_arm_description/meshes/link2_leg_1.stl" scale="0.001 0.001 0.001"/>
      </geometry>
    </collision>
  </link>
  <link name="Component38_1">
    <inertial>
      <origin xyz="-0.00019676045175197332 0.07614701661937778 -0.024295607856452628" rpy="0 0 0"/>
      <mass value="0.5585472030657777"/>
      <inertia ixx="0.002399" iyy="0.000727" izz="0.001674" ixy="-1e-05" iyz="-0.000564" ixz="-2e-06"/>
    </inertial>
    <visual>
      <origin xyz="0.07965 -0.155108 -0.1635" rpy="0 0 0"/>
      <geometry>
        <mesh filename="package://robot_arm_description/meshes/Component38_1.stl" scale="0.001 0.001 0.001"/>
      </geometry>
      <material name="silver"/>
    </visual>
    <collision>
      <origin xyz="0.07965 -0.155108 -0.1635" rpy="0 0 0"/>
      <geometry>
        <mesh filename="package://robot_arm_description/meshes/Component38_1.stl" scale="0.001 0.001 0.001"/>
      </geometry>
    </collision>
  </link>
  <link name="link2-1__3__1">
    <inertial>
      <origin xyz="-1.3877787807814457e-17 -0.07932718315389906 -0.04908356505084066" rpy="0 0 0"/>
      <mass value="0.5733792760793044"/>
      <inertia ixx="0.0022" iyy="0.000464" izz="0.001737" ixy="0.0" iyz="4e-06" ixz="0.0"/>
    </inertial>
    <visual>
      <origin xyz="0.07965 -0.130108 -0.1635" rpy="0 0 0"/>
      <geometry>
        <mesh filename="package://robot_arm_description/meshes/link2-1__3__1.stl" scale="0.001 0.001 0.001"/>
      </geometry>
      <material name="silver"/>
    </visual>
    <collision>
      <origin xyz="0.07965 -0.130108 -0.1635" rpy="0 0 0"/>
      <geometry>
        <mesh filename="package://robot_arm_description/meshes/link2-1__3__1.stl" scale="0.001 0.001 0.001"/>
      </geometry>
    </collision>
  </link>
  <link name="cap_1">
    <inertial>
      <origin xyz="-0.004167982156716682 5.901989065526525e-08 -9.569835239800484e-05" rpy="0 0 0"/>
      <mass value="0.1272431550006768"/>
      <inertia ixx="2.8e-05" iyy="2.3e-05" izz="2.3e-05" ixy="0.0" iyz="-0.0" ixz="-0.0"/>
    </inertial>
    <visual>
      <origin xyz="0.08165 0.005544 -0.1145" rpy="0 0 0"/>
      <geometry>
        <mesh filename="package://robot_arm_description/meshes/cap_1.stl" scale="0.001 0.001 0.001"/>
      </geometry>
      <material name="silver"/>
    </visual>
    <collision>
      <origin xyz="0.08165 0.005544 -0.1145" rpy="0 0 0"/>
      <geometry>
        <mesh filename="package://robot_arm_description/meshes/cap_1.stl" scale="0.001 0.001 0.001"/>
      </geometry>
    </collision>
  </link>
  <link name="motor1_1">
    <inertial>
      <origin xyz="-0.022681668247387272 5.9019806486482196e-08 -0.015028583770211434" rpy="0 0 0"/>
      <mass value="0.6640277986148614"/>
      <inertia ixx="0.000249" iyy="0.000301" izz="0.000169" ixy="0.0" iyz="0.0" ixz="1e-06"/>
    </inertial>
    <visual>
      <origin xyz="-0.04665 -0.287456 -0.1745" rpy="0 0 0"/>
      <geometry>
        <mesh filename="package://robot_arm_description/meshes/motor1_1.stl" scale="0.001 0.001 0.001"/>
      </geometry>
      <material name="silver"/>
    </visual>
    <collision>
      <origin xyz="-0.04665 -0.287456 -0.1745" rpy="0 0 0"/>
      <geometry>
        <mesh filename="package://robot_arm_description/meshes/motor1_1.stl" scale="0.001 0.001 0.001"/>
      </geometry>
    </collision>
  </link>
  <link name="adapter_a__1__1">
    <inertial>
      <origin xyz="-0.011954439967386052 5.902016975145585e-08 1.63912758366358e-09" rpy="0 0 0"/>
      <mass value="0.09838512042156751"/>
      <inertia ixx="1.5e-05" iyy="1.9e-05" izz="1.9e-05" ixy="0.0" iyz="0.0" ixz="-0.0"/>
    </inertial>
    <visual>
      <origin xyz="-0.00265 -0.287456 -0.1745" rpy="0 0 0"/>
      <geometry>
        <mesh filename="package://robot_arm_description/meshes/adapter_a__1__1.stl" scale="0.001 0.001 0.001"/>
      </geometry>
      <material name="silver"/>
    </visual>
    <collision>
      <origin xyz="-0.00265 -0.287456 -0.1745" rpy="0 0 0"/>
      <geometry>
        <mesh filename="package://robot_arm_description/meshes/adapter_a__1__1.stl" scale="0.001 0.001 0.001"/>
      </geometry>
    </collision>
  </link>
  <link name="gearbox1__1__1">
    <inertial>
      <origin xyz="-0.008155066400898983 5.901984367895352e-08 -9.027356989987911e-06" rpy="0 0 0"/>
      <mass value="2.0338757908094958"/>
      <inertia ixx="0.001172" iyy="0.001592" izz="0.001592" ixy="0.0" iyz="0.0" ixz="-1e-06"/>
    </inertial>
    <visual>
      <origin xyz="0.03805 -0.287456 -0.1745" rpy="0 0 0"/>
      <geometry>
        <mesh filename="package://robot_arm_description/meshes/gearbox1__1__1.stl" scale="0.001 0.001 0.001"/>
      </geometry>
      <material name="silver"/>
    </visual>
    <collision>
      <origin xyz="0.03805 -0.287456 -0.1745" rpy="0 0 0"/>
      <geometry>
        <mesh filename="package://robot_arm_description/meshes/gearbox1__1__1.stl" scale="0.001 0.001 0.001"/>
      </geometry>
    </collision>
  </link>
  <link name="cap2_1">
    <inertial>
      <origin xyz="0.012332017843283541 5.90198901417871e-08 -9.569999152628239e-05" rpy="0 0 0"/>
      <mass value="0.12724315500067693"/>
      <inertia ixx="2.8e-05" iyy="2.3e-05" izz="2.3e-05" ixy="0.0" iyz="-0.0" ixz="-0.0"/>
    </inertial>
    <visual>
      <origin xyz="0.11355 -0.287456 -0.1745" rpy="0 0 0"/>
      <geometry>
        <mesh filename="package://robot_arm_description/meshes/cap2_1.stl" scale="0.001 0.001 0.001"/>
      </geometry>
      <material name="silver"/>
    </visual>
    <collision>
      <origin xyz="0.11355 -0.287456 -0.1745" rpy="0 0 0"/>
      <geometry>
        <mesh filename="package://robot_arm_description/meshes/cap2_1.stl" scale="0.001 0.001 0.001"/>
      </geometry>
    </collision>
  </link>
  <link name="link3_1">
    <inertial>
      <origin xyz="0.0020000000000000434 -0.07433116476400226 0.043061485284185685" rpy="0 0 0"/>
      <mass value="0.8034510771086975"/>
      <inertia ixx="0.004894" iyy="0.001217" izz="0.00368" ixy="0.0" iyz="0.000997" ixz="-0.0"/>
    </inertial>
    <visual>
      <origin xyz="0.09705 -0.287456 -0.1745" rpy="0 0 0"/>
      <geometry>
        <mesh filename="package://robot_arm_description/meshes/link3_1.stl" scale="0.001 0.001 0.001"/>
      </geometry>
      <material name="silver"/>
    </visual>
    <collision>
      <origin xyz="0.09705 -0.287456 -0.1745" rpy="0 0 0"/>
      <geometry>
        <mesh filename="package://robot_arm_description/meshes/link3_1.stl" scale="0.001 0.001 0.001"/>
      </geometry>
    </collision>
  </link>
  <link name="link3_leg_1">
    <inertial>
      <origin xyz="0.09715000000000007 9.047525997840644e-08 0.0009999999999996678" rpy="0 0 0"/>
      <mass value="0.3308579843753697"/>
      <inertia ixx="0.000343" iyy="0.000976" izz="0.001319" ixy="-0.0" iyz="0.0" ixz="0.0"/>
    </inertial>
    <visual>
      <origin xyz="0.09705 -0.180716 -0.2825" rpy="0 0 0"/>
      <geometry>
        <mesh filename="package://robot_arm_description/meshes/link3_leg_1.stl" scale="0.001 0.001 0.001"/>
      </geometry>
      <material name="silver"/>
    </visual>
    <collision>
      <origin xyz="0.09705 -0.180716 -0.2825" rpy="0 0 0"/>
      <geometry>
        <mesh filename="package://robot_arm_description/meshes/link3_leg_1.stl" scale="0.001 0.001 0.001"/>
      </geometry>
    </collision>
  </link>
  <link name="link3_leg2_1">
    <inertial>
      <origin xyz="0.09715000000000008 -0.018238990724664728 -0.0010000000000002784" rpy="0 0 0"/>
      <mass value="0.2226363143753701"/>
      <inertia ixx="0.000104" iyy="0.000663" izz="0.000768" ixy="-0.0" iyz="-0.0" ixz="0.0"/>
    </inertial>
    <visual>
      <origin xyz="0.09705 -0.180716 -0.1865" rpy="0 0 0"/>
      <geometry>
        <mesh filename="package://robot_arm_description/meshes/link3_leg2_1.stl" scale="0.001 0.001 0.001"/>
      </geometry>
      <material name="silver"/>
    </visual>
    <collision>
      <origin xyz="0.09705 -0.180716 -0.1865" rpy="0 0 0"/>
      <geometry>
        <mesh filename="package://robot_arm_description/meshes/link3_leg2_1.stl" scale="0.001 0.001 0.001"/>
      </geometry>
    </collision>
  </link>
  <link name="link4_1">
    <inertial>
      <origin xyz="0.03775644304825835 -0.0019999793697433738 -2.7755575615628914e-16" rpy="0 0 0"/>
      <mass value="0.21082599155250994"/>
      <inertia ixx="0.000175" iyy="0.000259" izz="8.5e-05" ixy="0.0" iyz="-0.0" ixz="0.0"/>
    </inertial>
    <visual>
      <origin xyz="0.09705 -0.092829 -0.2345" rpy="0 0 0"/>
      <geometry>
        <mesh filename="package://robot_arm_description/meshes/link4_1.stl" scale="0.001 0.001 0.001"/>
      </geometry>
      <material name="silver"/>
    </visual>
    <collision>
      <origin xyz="0.09705 -0.092829 -0.2345" rpy="0 0 0"/>
      <geometry>
        <mesh filename="package://robot_arm_description/meshes/link4_1.stl" scale="0.001 0.001 0.001"/>
      </geometry>
    </collision>
  </link>
  <link name="link5_1">
    <inertial>
      <origin xyz="0.0020000000000001197 -0.047072781744556015 -0.0017182952557845133" rpy="0 0 0"/>
      <mass value="0.2576677637629673"/>
      <inertia ixx="0.000397" iyy="0.000216" izz="0.000182" ixy="0.0" iyz="-1.7e-05" ixz="-0.0"/>
    </inertial>
    <visual>
      <origin xyz="0.0284 -0.092829 -0.2345" rpy="0 0 0"/>
      <geometry>
        <mesh filename="package://robot_arm_description/meshes/link5_1.stl" scale="0.001 0.001 0.001"/>
      </geometry>
      <material name="silver"/>
    </visual>
    <collision>
      <origin xyz="0.0284 -0.092829 -0.2345" rpy="0 0 0"/>
      <geometry>
        <mesh filename="package://robot_arm_description/meshes/link5_1.stl" scale="0.001 0.001 0.001"/>
      </geometry>
    </collision>
  </link>
  <link name="adapter_1">
    <inertial>
      <origin xyz="-0.00139999999999987 0.0055440590197324245 -0.004500000000000309" rpy="0 0 0"/>
      <mass value="0.037276333994375375"/>
      <inertia ixx="4e-06" iyy="2e-06" izz="2e-06" ixy="0.0" iyz="-0.0" ixz="0.0"/>
    </inertial>
    <visual>
      <origin xyz="0.0283 -0.023912 -0.239" rpy="0 0 0"/>
      <geometry>
        <mesh filename="package://robot_arm_description/meshes/adapter_1.stl" scale="0.001 0.001 0.001"/>
      </geometry>
      <material name="silver"/>
    </visual>
    <collision>
      <origin xyz="0.0283 -0.023912 -0.239" rpy="0 0 0"/>
      <geometry>
        <mesh filename="package://robot_arm_description/meshes/adapter_1.stl" scale="0.001 0.001 0.001"/>
      </geometry>
    </collision>
  </link>
  <link name="motor2_1">
    <inertial>
      <origin xyz="0.023894893703177305 5.901981185371663e-08 -0.015073330886626712" rpy="0 0 0"/>
      <mass value="0.6620566191194474"/>
      <inertia ixx="0.000249" iyy="0.000299" izz="0.000168" ixy="0.0" iyz="0.0" ixz="1e-06"/>
    </inertial>
    <visual>
      <origin xyz="0.0244 -0.029456 -0.2345" rpy="0 0 0"/>
      <geometry>
        <mesh filename="package://robot_arm_description/meshes/motor2_1.stl" scale="0.001 0.001 0.001"/>
      </geometry>
      <material name="silver"/>
    </visual>
    <collision>
      <origin xyz="0.0244 -0.029456 -0.2345" rpy="0 0 0"/>
      <geometry>
        <mesh filename="package://robot_arm_description/meshes/motor2_1.stl" scale="0.001 0.001 0.001"/>
      </geometry>
    </collision>
  </link>
  <link name="link2__1__1">
    <inertial>
      <origin xyz="0.0003862140672195938 -0.045556186071226995 -0.008927818295609763" rpy="0 0 0"/>
      <mass value="0.20741862160121777"/>
      <inertia ixx="0.00033" iyy="3.7e-05" izz="0.000318" ixy="3.1e-05" iyz="1.6e-05" ixz="-3e-06"/>
    </inertial>
    <visual>
      <origin xyz="0.035 -0.029456 -0.245" rpy="0 0 0"/>
      <geometry>
        <mesh filename="package://robot_arm_description/meshes/link2__1__1.stl" scale="0.001 0.001 0.001"/>
      </geometry>
      <material name="silver"/>
    </visual>
    <collision>
      <origin xyz="0.035 -0.029456 -0.245" rpy="0 0 0"/>
      <geometry>
        <mesh filename="package://robot_arm_description/meshes/link2__1__1.stl" scale="0.001 0.001 0.001"/>
      </geometry>
    </collision>
  </link>
  <link name="top_1">
    <inertial>
      <origin xyz="0.03806588078503643 0.012385240629570277 0.004966323971638209" rpy="0 0 0"/>
      <mass value="0.11483450819161148"/>
      <inertia ixx="2.4e-05" iyy="8.5e-05" izz="0.0001" ixy="7e-06" iyz="2e-06" ixz="-0.0"/>
    </inertial>
    <visual>
      <origin xyz="0.04 0.064544 -0.2485" rpy="0 0 0"/>
      <geometry>
        <mesh filename="package://robot_arm_description/meshes/top_1.stl" scale="0.001 0.001 0.001"/>
      </geometry>
      <material name="silver"/>
    </visual>
    <collision>
      <origin xyz="0.04 0.064544 -0.2485" rpy="0 0 0"/>
      <geometry>
        <mesh filename="package://robot_arm_description/meshes/top_1.stl" scale="0.001 0.001 0.001"/>
      </geometry>
    </collision>
  </link>
  <link name="bottom_1">
    <inertial>
      <origin xyz="0.037893096722248956 0.015038584856599556 -0.004588054333293401" rpy="0 0 0"/>
      <mass value="0.12615164501277876"/>
      <inertia ixx="3.1e-05" iyy="8.4e-05" izz="0.000103" ixy="7e-06" iyz="-5e-06" ixz="4e-06"/>
    </inertial>
    <visual>
      <origin xyz="0.04 0.064544 -0.232" rpy="0 0 0"/>
      <geometry>
        <mesh filename="package://robot_arm_description/meshes/bottom_1.stl" scale="0.001 0.001 0.001"/>
      </geometry>
      <material name="silver"/>
    </visual>
    <collision>
      <origin xyz="0.04 0.064544 -0.232" rpy="0 0 0"/>
      <geometry>
        <mesh filename="package://robot_arm_description/meshes/bottom_1.stl" scale="0.001 0.001 0.001"/>
      </geometry>
    </collision>
  </link>
  <link name="link3-1_1">
    <inertial>
      <origin xyz="-0.001999999999999877 0.03378837359224662 -0.0657331113600699" rpy="0 0 0"/>
      <mass value="0.8186445791058825"/>
      <inertia ixx="0.005008" iyy="0.001246" izz="0.003764" ixy="0.0" iyz="0.001045" ixz="-0.0"/>
    </inertial>
    <visual>
      <origin xyz="-0.09725 -0.180716 -0.2825" rpy="0 0 0"/>
      <geometry>
        <mesh filename="package://robot_arm_description/meshes/link3-1_1.stl" scale="0.001 0.001 0.001"/>
      </geometry>
      <material name="silver"/>
    </visual>
    <collision>
      <origin xyz="-0.09725 -0.180716 -0.2825" rpy="0 0 0"/>
      <geometry>
        <mesh filename="package://robot_arm_description/meshes/link3-1_1.stl" scale="0.001 0.001 0.001"/>
      </geometry>
    </collision>
  </link>
  <link name="link4-1_1">
    <inertial>
      <origin xyz="-0.03775644304825801 -0.0019999793697431656 -3.0531133177191805e-16" rpy="0 0 0"/>
      <mass value="0.21082599155250997"/>
      <inertia ixx="0.000175" iyy="0.000259" izz="8.5e-05" ixy="-0.0" iyz="-0.0" ixz="0.0"/>
    </inertial>
    <visual>
      <origin xyz="-0.09725 -0.092829 -0.2345" rpy="0 0 0"/>
      <geometry>
        <mesh filename="package://robot_arm_description/meshes/link4-1_1.stl" scale="0.001 0.001 0.001"/>
      </geometry>
      <material name="silver"/>
    </visual>
    <collision>
      <origin xyz="-0.09725 -0.092829 -0.2345" rpy="0 0 0"/>
      <geometry>
        <mesh filename="package://robot_arm_description/meshes/link4-1_1.stl" scale="0.001 0.001 0.001"/>
      </geometry>
    </collision>
  </link>
  <link name="link5-1_1">
    <inertial>
      <origin xyz="-0.001999999999999391 -0.04590089720740974 -0.001841830468614053" rpy="0 0 0"/>
      <mass value="0.24038547715832267"/>
      <inertia ixx="0.000388" iyy="0.000214" izz="0.000174" ixy="0.0" iyz="-1.8e-05" ixz="0.0"/>
    </inertial>
    <visual>
      <origin xyz="-0.0286 -0.092829 -0.2345" rpy="0 0 0"/>
      <geometry>
        <mesh filename="package://robot_arm_description/meshes/link5-1_1.stl" scale="0.001 0.001 0.001"/>
      </geometry>
      <material name="silver"/>
    </visual>
    <collision>
      <origin xyz="-0.0286 -0.092829 -0.2345" rpy="0 0 0"/>
      <geometry>
        <mesh filename="package://robot_arm_description/meshes/link5-1_1.stl" scale="0.001 0.001 0.001"/>
      </geometry>
    </collision>
  </link>
  <link name="adapter_b__1___1__1">
    <inertial>
      <origin xyz="0.0015112369977055007 0.005544059019721461 -0.004500000000000309" rpy="0 0 0"/>
      <mass value="0.0836288961017048"/>
      <inertia ixx="1.4e-05" iyy="9e-06" izz="9e-06" ixy="-0.0" iyz="0.0" ixz="0.0"/>
    </inertial>
    <visual>
      <origin xyz="-0.0287 -0.023912 -0.239" rpy="0 0 0"/>
      <geometry>
        <mesh filename="package://robot_arm_description/meshes/adapter_b__1___1__1.stl" scale="0.001 0.001 0.001"/>
      </geometry>
      <material name="silver"/>
    </visual>
    <collision>
      <origin xyz="-0.0287 -0.023912 -0.239" rpy="0 0 0"/>
      <geometry>
        <mesh filename="package://robot_arm_description/meshes/adapter_b__1___1__1.stl" scale="0.001 0.001 0.001"/>
      </geometry>
    </collision>
  </link>
  <link name="link1__1__1">
    <inertial>
      <origin xyz="-0.003259546931585394 0.05352825414872342 -0.0128293029891631" rpy="0 0 0"/>
      <mass value="0.1900850226097608"/>
      <inertia ixx="0.000277" iyy="2.5e-05" izz="0.000255" ixy="-8e-06" iyz="1.1e-05" ixz="1e-06"/>
    </inertial>
    <visual>
      <origin xyz="-0.0419 0.064544 -0.2485" rpy="0 0 0"/>
      <geometry>
        <mesh filename="package://robot_arm_description/meshes/link1__1__1.stl" scale="0.001 0.001 0.001"/>
      </geometry>
      <material name="silver"/>
    </visual>
    <collision>
      <origin xyz="-0.0419 0.064544 -0.2485" rpy="0 0 0"/>
      <geometry>
        <mesh filename="package://robot_arm_description/meshes/link1__1__1.stl" scale="0.001 0.001 0.001"/>
      </geometry>
    </collision>
  </link>
  <link name="XL430_T_1">
    <inertial>
      <origin xyz="0.019105590233629958 0.022231451173800897 -0.0045128493934226965" rpy="0 0 0"/>
      <mass value="0.34622507558019666"/>
      <inertia ixx="5.7e-05" iyy="8.2e-05" izz="9.4e-05" ixy="1e-06" iyz="-0.0" ixz="0.0"/>
    </inertial>
    <visual>
      <origin xyz="0.01995 0.071088 -0.24475" rpy="0 0 0"/>
      <geometry>
        <mesh filename="package://robot_arm_description/meshes/XL430_T_1.stl" scale="0.001 0.001 0.001"/>
      </geometry>
      <material name="silver"/>
    </visual>
    <collision>
      <origin xyz="0.01995 0.071088 -0.24475" rpy="0 0 0"/>
      <geometry>
        <mesh filename="package://robot_arm_description/meshes/XL430_T_1.stl" scale="0.001 0.001 0.001"/>
      </geometry>
    </collision>
  </link>
  <link name="connector_1__1">
    <inertial>
      <origin xyz="-4.886872156939503e-13 -0.0048213765272196035 -2.237968976803728e-10" rpy="0 0 0"/>
      <mass value="0.14836014599953082"/>
      <inertia ixx="5.9e-05" iyy="0.000115" izz="5.9e-05" ixy="-0.0" iyz="-0.0" ixz="0.0"/>
    </inertial>
    <visual>
      <origin xyz="-0.01095 0.069444 -0.2395" rpy="0 0 0"/>
      <geometry>
        <mesh filename="package://robot_arm_description/meshes/connector_1__1.stl" scale="0.001 0.001 0.001"/>
      </geometry>
      <material name="silver"/>
    </visual>
    <collision>
      <origin xyz="-0.01095 0.069444 -0.2395" rpy="0 0 0"/>
      <geometry>
        <mesh filename="package://robot_arm_description/meshes/connector_1__1.stl" scale="0.001 0.001 0.001"/>
      </geometry>
    </collision>
  </link>
  <link name="module_connector_5axis_Component41_1">
    <inertial>
      <origin xyz="9.540979117872439e-17 -0.0357348296843351 -2.235175100562259e-10" rpy="0 0 0"/>
      <mass value="1.9126732622839608"/>
      <inertia ixx="0.001388" iyy="0.001027" izz="0.001388" ixy="0.0" iyz="-0.0" ixz="0.0"/>
    </inertial>
    <visual>
      <origin xyz="-0.01095 0.074544 -0.2395" rpy="0 0 0"/>
      <geometry>
        <mesh filename="package://robot_arm_description/meshes/module_connector_5axis_Component41_1.stl" scale="0.001 0.001 0.001"/>
      </geometry>
      <material name="silver"/>
    </visual>
    <collision>
      <origin xyz="-0.01095 0.074544 -0.2395" rpy="0 0 0"/>
      <geometry>
        <mesh filename="package://robot_arm_description/meshes/module_connector_5axis_Component41_1.stl" scale="0.001 0.001 0.001"/>
      </geometry>
    </collision>
  </link>
  <joint name="Rigid 20" type="fixed">
    <origin xyz="0.0 0.0 0.004" rpy="0 0 0"/>
    <parent link="base_link"/>
    <child link="motor0_1"/>
  </joint>
  <joint name="Rigid 21" type="fixed">
    <origin xyz="0.0 0.0 0.004" rpy="0 0 0"/>
    <parent link="base_link"/>
    <child link="lower_cylinder_1"/>
  </joint>
  <joint name="Rigid 22" type="fixed">
    <origin xyz="0.0 0.0 0.0465" rpy="0 0 0"/>
    <parent link="lower_cylinder_1"/>
    <child link="powertrain_1"/>
  </joint>
  <joint name="joint_1" type="revolute">
    <origin xyz="0.0 0.0 0.0465" rpy="0 0 0"/>
    <parent link="lower_cylinder_1"/>
    <child link="base_plate_1"/>
    <axis xyz="0.0 0.0 1.0"/>
    <limit upper="3.141593" lower="-3.141593" effort="100" velocity="100"/>
  </joint>
  <joint name="Rigid 24" type="fixed">
    <origin xyz="0.0 -0.01 0.0085" rpy="0 0 0"/>
    <parent link="base_plate_1"/>
    <child link="link1-1_1"/>
  </joint>
  <joint name="Rigid 25" type="fixed">
    <origin xyz="0.0 -0.01 0.0085" rpy="0 0 0"/>
    <parent link="base_plate_1"/>
    <child link="link1_1"/>
  </joint>
  <joint name="Rigid 26" type="fixed">
    <origin xyz="-0.06215 0.004643 0.06" rpy="0 0 0"/>
    <parent link="link1-1_1"/>
    <child link="gearbox1_1"/>
  </joint>
  <joint name="Rigid 27" type="fixed">
    <origin xyz="0.0675 -0.005731 0.0" rpy="0 0 0"/>
    <parent link="gearbox1_1"/>
    <child link="adapter_a_1"/>
  </joint>
  <joint name="Rigid 28" type="fixed">
    <origin xyz="0.0103 0.005544 -0.0045" rpy="0 0 0"/>
    <parent link="adapter_a_1"/>
    <child link="motor_1"/>
  </joint>
  <joint name="joint_2" type="revolute">
    <origin xyz="0.0465 0.0 0.0" rpy="0 0 0"/>
    <parent link="motor_1"/>
    <child link="adapter_b_1"/>
    <axis xyz="-1.0 0.0 0.0"/>
    <limit upper="0.0" lower="-3.141593" effort="100" velocity="100"/>
  </joint>
  <joint name="Rigid 30" type="fixed">
    <origin xyz="0.0148 0.0 0.0" rpy="0 0 0"/>
    <parent link="adapter_b_1"/>
    <child link="Component40_1"/>
  </joint>
  <joint name="Rigid 31" type="fixed">
    <origin xyz="0.002 0.15 -0.001" rpy="0 0 0"/>
    <parent link="Component40_1"/>
    <child link="link2_1"/>
  </joint>
  <joint name="Rigid 32" type="fixed">
    <origin xyz="-0.002 0.143 0.061" rpy="0 0 0"/>
    <parent link="link2_1"/>
    <child link="adapter_b__1__1"/>
  </joint>
  <joint name="Rigid 33" type="fixed">
    <origin xyz="0.002 0.013819 -0.047" rpy="0 0 0"/>
    <parent link="link2_1"/>
    <child link="link2_leg2_1"/>
  </joint>
  <joint name="Rigid 34" type="fixed">
    <origin xyz="0.002 0.135652 0.049" rpy="0 0 0"/>
    <parent link="Component40_1"/>
    <child link="link2_leg_1"/>
  </joint>
  <joint name="Rigid 35" type="fixed">
    <origin xyz="-0.1586 0.025 0.0" rpy="0 0 0"/>
    <parent link="link2_leg_1"/>
    <child link="Component38_1"/>
  </joint>
  <joint name="Rigid 36" type="fixed">
    <origin xyz="-0.1586 0.0 0.0" rpy="0 0 0"/>
    <parent link="link2_leg_1"/>
    <child link="link2-1__3__1"/>
  </joint>
  <joint name="Rigid 37" type="fixed">
    <origin xyz="-0.002 -0.135652 -0.049" rpy="0 0 0"/>
    <parent link="link2-1__3__1"/>
    <child link="cap_1"/>
  </joint>
  <joint name="Rigid 38" type="fixed">
    <origin xyz="-0.0303 0.0 0.0" rpy="0 0 0"/>
    <parent link="adapter_b__1__1"/>
    <child link="motor1_1"/>
  </joint>
  <joint name="Rigid 39" type="fixed">
    <origin xyz="-0.044 0.0 0.0" rpy="0 0 0"/>
    <parent link="motor1_1"/>
    <child link="adapter_a__1__1"/>
  </joint>
  <joint name="Rigid 40" type="fixed">
    <origin xyz="-0.0407 0.0 0.0" rpy="0 0 0"/>
    <parent link="adapter_a__1__1"/>
    <child link="gearbox1__1__1"/>
  </joint>
  <joint name="joint_3" type="revolute">
    <origin xyz="-0.0755 0.0 0.0" rpy="0 0 0"/>
    <parent link="gearbox1__1__1"/>
    <child link="cap2_1"/>
    <axis xyz="-1.0 0.0 0.0"/>
    <limit upper="3.141593" lower="0.0" effort="100" velocity="100"/>
  </joint>
  <joint name="Rigid 43" type="fixed">
    <origin xyz="0.0165 0.0 0.0" rpy="0 0 0"/>
    <parent link="cap2_1"/>
    <child link="link3_1"/>
  </joint>
  <joint name="Rigid 44" type="fixed">
    <origin xyz="0.0 -0.10674 0.108" rpy="0 0 0"/>
    <parent link="link3_1"/>
    <child link="link3_leg_1"/>
  </joint>
  <joint name="Rigid 45" type="fixed">
    <origin xyz="0.0 -0.10674 0.012" rpy="0 0 0"/>
    <parent link="link3_1"/>
    <child link="link3_leg2_1"/>
  </joint>
  <joint name="Rigid 46" type="fixed">
    <origin xyz="0.0 -0.194627 0.06" rpy="0 0 0"/>
    <parent link="link3_1"/>
    <child link="link4_1"/>
  </joint>
  <joint name="Rigid 47" type="fixed">
    <origin xyz="0.06865 0.0 0.0" rpy="0 0 0"/>
    <parent link="link4_1"/>
    <child link="link5_1"/>
  </joint>
  <joint name="joint_4" type="revolute">
    <origin xyz="0.0001 -0.068917 0.0045" rpy="0 0 0"/>
    <parent link="link5_1"/>
    <child link="adapter_1"/>
    <axis xyz="-1.0 0.0 0.0"/>
    <limit upper="1.570796" lower="-1.570796" effort="100" velocity="100"/>
  </joint>
  <joint name="Rigid 49" type="fixed">
    <origin xyz="0.0039 0.005544 -0.0045" rpy="0 0 0"/>
    <parent link="adapter_1"/>
    <child link="motor2_1"/>
  </joint>
  <joint name="Rigid 50" type="fixed">
    <origin xyz="-0.0067 0.005544 0.006" rpy="0 0 0"/>
    <parent link="adapter_1"/>
    <child link="link2__1__1"/>
  </joint>
  <joint name="Rigid 51" type="fixed">
    <origin xyz="-0.005 -0.094 0.0035" rpy="0 0 0"/>
    <parent link="link2__1__1"/>
    <child link="top_1"/>
  </joint>
  <joint name="Rigid 52" type="fixed">
    <origin xyz="-0.005 -0.094 -0.013" rpy="0 0 0"/>
    <parent link="link2__1__1"/>
    <child link="bottom_1"/>
  </joint>
  <joint name="Rigid 62" type="fixed">
    <origin xyz="0.1943 0.0 0.0" rpy="0 0 0"/>
    <parent link="link3_leg_1"/>
    <child link="link3-1_1"/>
  </joint>
  <joint name="Rigid 63" type="fixed">
    <origin xyz="0.0 -0.087887 -0.048" rpy="0 0 0"/>
    <parent link="link3-1_1"/>
    <child link="link4-1_1"/>
  </joint>
  <joint name="Rigid 64" type="fixed">
    <origin xyz="-0.06865 0.0 0.0" rpy="0 0 0"/>
    <parent link="link4-1_1"/>
    <child link="link5-1_1"/>
  </joint>
  <joint name="Rigid 65" type="fixed">
    <origin xyz="0.0001 -0.068917 0.0045" rpy="0 0 0"/>
    <parent link="link5-1_1"/>
    <child link="adapter_b__1___1__1"/>
  </joint>
  <joint name="Rigid 66" type="fixed">
    <origin xyz="0.0819 0.0 0.0" rpy="0 0 0"/>
    <parent link="top_1"/>
    <child link="link1__1__1"/>
  </joint>
  <joint name="Rigid 71" type="fixed">
    <origin xyz="0.01505 -0.100544 -0.00025" rpy="0 0 0"/>
    <parent link="link2__1__1"/>
    <child link="XL430_T_1"/>
  </joint>
  <joint name="joint_5" type="revolute">
    <origin xyz="0.0309 0.001644 -0.00525" rpy="0 0 0"/>
    <parent link="XL430_T_1"/>
    <child link="connector_1__1"/>
    <axis xyz="-0.0 -1.0 0.0"/>
    <limit upper="3.141593" lower="-3.141593" effort="100" velocity="100"/>
  </joint>
  <joint name="Rigid 73" type="fixed">
    <origin xyz="0.0 -0.0051 0.0" rpy="0 0 0"/>
    <parent link="connector_1__1"/>
    <child link="module_connector_5axis_Component41_1"/>
  </joint>
</robot>
