<!-- gripper_a: 극한로봇 그리퍼 모듈 (파라렐 4절링크 그리퍼, XC430 x2 구동) -->
<!-- Fusion 360 fusion2urdf export를 robot_arm_description 패키지 구조로 편입:
     - 모든 link/joint 이름에 gripper_a_ prefix (다른 그리퍼 모듈과 충돌 방지, 그리퍼 모듈화 가이드 §1-2)
     - mesh 경로를 robot_arm_description/meshes/grippers/gripper_a/ 로 교체
     - raw export에 동일 이름으로 중복 선언된 link(link5/link5_2/link6/component53_1)가
       각각 2개의 부모 joint(joint9/10, joint17/18, joint11/12, joint19/20)를 가져 URDF 트리 규칙 위반
       (평행 4절링크 특유의 닫힌 루프를 그대로 export한 것). 루프를 끊어 단일 트리로 단순화:
       link1側 joint(9,17)·link3側 joint(11,19)만 남기고 link2/link4側 중복 joint(10,12,18,20)는 제거.
       -> link2/link4는 top_plate에 직접 매달린 독립 조인트로 렌더링되어 항상 평행 유지되는
       실제 기구 커플링은 반영되지 않음(0도 홈포즈 시각화/충돌형상 확인용, 구동 로직은 실서보 2개(XC430 x2)로 별도 처리) -->
<robot xmlns:xacro="http://www.ros.org/wiki/xacro" name="gripper_a">

<link name="gripper_a_base_link">
  <inertial>
    <origin xyz="-0.06930330432389567 0.1480589720476463 -0.025544286170088252" rpy="0 0 0" />
    <mass value="0.9719353305681612" />
    <inertia ixx="0.00049" iyy="0.000557" izz="0.000578" ixy="-1e-06" iyz="-9e-06" ixz="0.000116" />
  </inertial>
  <visual>
    <origin xyz="0 0 0" rpy="0 0 0" />
    <geometry>
      <mesh filename="package://robot_arm_description/meshes/grippers/gripper_a/base_link.stl" scale="0.001 0.001 0.001" />
    </geometry>
    <material name="silver" />
  </visual>
  <collision>
    <origin xyz="0 0 0" rpy="0 0 0" />
    <geometry>
      <mesh filename="package://robot_arm_description/meshes/grippers/gripper_a/base_link.stl" scale="0.001 0.001 0.001" />
    </geometry>
  </collision>
</link>


<link name="gripper_a_link1">
  <inertial>
    <origin xyz="0.025240953749213958 0.02424613800333089 0.004999999999999901" rpy="0 0 0" />
    <mass value="0.0851839232743157" />
    <inertia ixx="2.8e-05" iyy="3e-05" izz="5.7e-05" ixy="-2.7e-05" iyz="-0.0" ixz="0.0" />
  </inertial>
  <visual>
    <origin xyz="0.038971 -0.164837 0.0" rpy="0 0 0" />
    <geometry>
      <mesh filename="package://robot_arm_description/meshes/grippers/gripper_a/link1.stl" scale="0.001 0.001 0.001" />
    </geometry>
    <material name="silver" />
  </visual>
  <collision>
    <origin xyz="0.038971 -0.164837 0.0" rpy="0 0 0" />
    <geometry>
      <mesh filename="package://robot_arm_description/meshes/grippers/gripper_a/link1.stl" scale="0.001 0.001 0.001" />
    </geometry>
  </collision>
</link>


<link name="gripper_a_link3">
  <inertial>
    <origin xyz="0.018230231416085364 -0.02987724109270805 0.004999999999999947" rpy="0 0 0" />
    <mass value="0.08518393559594871" />
    <inertia ixx="4.2e-05" iyy="1.7e-05" izz="5.7e-05" ixy="2.4e-05" iyz="0.0" ixz="0.0" />
  </inertial>
  <visual>
    <origin xyz="0.038971 -0.128737 0.0" rpy="0 0 0" />
    <geometry>
      <mesh filename="package://robot_arm_description/meshes/grippers/gripper_a/link3.stl" scale="0.001 0.001 0.001" />
    </geometry>
    <material name="silver" />
  </visual>
  <collision>
    <origin xyz="0.038971 -0.128737 0.0" rpy="0 0 0" />
    <geometry>
      <mesh filename="package://robot_arm_description/meshes/grippers/gripper_a/link3.stl" scale="0.001 0.001 0.001" />
    </geometry>
  </collision>
</link>


<link name="gripper_a_link2">
  <inertial>
    <origin xyz="0.02524079026132333 0.024246225707795138 0.004999999999999907" rpy="0 0 0" />
    <mass value="0.06678651495220049" />
    <inertia ixx="2e-05" iyy="2.2e-05" izz="4.1e-05" ixy="-2e-05" iyz="0.0" ixz="-0.0" />
  </inertial>
  <visual>
    <origin xyz="0.014093 -0.154787 0.0" rpy="0 0 0" />
    <geometry>
      <mesh filename="package://robot_arm_description/meshes/grippers/gripper_a/link2.stl" scale="0.001 0.001 0.001" />
    </geometry>
    <material name="silver" />
  </visual>
  <collision>
    <origin xyz="0.014093 -0.154787 0.0" rpy="0 0 0" />
    <geometry>
      <mesh filename="package://robot_arm_description/meshes/grippers/gripper_a/link2.stl" scale="0.001 0.001 0.001" />
    </geometry>
  </collision>
</link>


<link name="gripper_a_link4">
  <inertial>
    <origin xyz="0.018230065239373604 -0.029877294933871715 0.004999999999999914" rpy="0 0 0" />
    <mass value="0.06678651495224165" />
    <inertia ixx="3e-05" iyy="1.2e-05" izz="4.1e-05" ixy="1.8e-05" iyz="-0.0" ixz="-0.0" />
  </inertial>
  <visual>
    <origin xyz="0.014093 -0.138787 0.0" rpy="0 0 0" />
    <geometry>
      <mesh filename="package://robot_arm_description/meshes/grippers/gripper_a/link4.stl" scale="0.001 0.001 0.001" />
    </geometry>
    <material name="silver" />
  </visual>
  <collision>
    <origin xyz="0.014093 -0.138787 0.0" rpy="0 0 0" />
    <geometry>
      <mesh filename="package://robot_arm_description/meshes/grippers/gripper_a/link4.stl" scale="0.001 0.001 0.001" />
    </geometry>
  </collision>
</link>


<link name="gripper_a_link5">
  <inertial>
    <origin xyz="0.016772894969398076 -0.00818690525076679 0.004999999999999888" rpy="0 0 0" />
    <mass value="0.050250119706585376" />
    <inertia ixx="4e-06" iyy="1.2e-05" izz="1.5e-05" ixy="6e-06" iyz="-0.0" ixz="-0.0" />
  </inertial>
  <visual>
    <origin xyz="-0.011511 -0.213329 -0.01" rpy="0 0 0" />
    <geometry>
      <mesh filename="package://robot_arm_description/meshes/grippers/gripper_a/link5.stl" scale="0.001 0.001 0.001" />
    </geometry>
    <material name="silver" />
  </visual>
  <collision>
    <origin xyz="-0.011511 -0.213329 -0.01" rpy="0 0 0" />
    <geometry>
      <mesh filename="package://robot_arm_description/meshes/grippers/gripper_a/link5.stl" scale="0.001 0.001 0.001" />
    </geometry>
  </collision>
</link>


<link name="gripper_a_link6">
  <inertial>
    <origin xyz="0.016772418745376695 0.008186864045676201 0.005000000001134073" rpy="0 0 0" />
    <mass value="0.050250119235721834" />
    <inertia ixx="4e-06" iyy="1.2e-05" izz="1.5e-05" ixy="-6e-06" iyz="-0.0" ixz="-0.0" />
  </inertial>
  <visual>
    <origin xyz="0.00251 -0.068983 -0.01" rpy="0 0 0" />
    <geometry>
      <mesh filename="package://robot_arm_description/meshes/grippers/gripper_a/link6.stl" scale="0.001 0.001 0.001" />
    </geometry>
    <material name="silver" />
  </visual>
  <collision>
    <origin xyz="0.00251 -0.068983 -0.01" rpy="0 0 0" />
    <geometry>
      <mesh filename="package://robot_arm_description/meshes/grippers/gripper_a/link6.stl" scale="0.001 0.001 0.001" />
    </geometry>
  </collision>
</link>


<link name="gripper_a_plate2">
  <inertial>
    <origin xyz="0.03765889407274898 -0.02538098094645444 -0.017000000000000397" rpy="0 0 0" />
    <mass value="0.0928673984319522" />
    <inertia ixx="1.2e-05" iyy="3.1e-05" izz="1.9e-05" ixy="0.0" iyz="-0.0" ixz="-0.0" />
  </inertial>
  <visual>
    <origin xyz="-0.030604 -0.209596 -0.019" rpy="0 0 0" />
    <geometry>
      <mesh filename="package://robot_arm_description/meshes/grippers/gripper_a/plate2.stl" scale="0.001 0.001 0.001" />
    </geometry>
    <material name="silver" />
  </visual>
  <collision>
    <origin xyz="-0.030604 -0.209596 -0.019" rpy="0 0 0" />
    <geometry>
      <mesh filename="package://robot_arm_description/meshes/grippers/gripper_a/plate2.stl" scale="0.001 0.001 0.001" />
    </geometry>
  </collision>
</link>


<link name="gripper_a_plate1">
  <inertial>
    <origin xyz="0.052262323030069044 0.03664491380276268 -0.018000000000000082" rpy="0 0 0" />
    <mass value="0.09286739843195235" />
    <inertia ixx="1.2e-05" iyy="3.1e-05" izz="1.9e-05" ixy="-0.0" iyz="0.0" ixz="-0.0" />
  </inertial>
  <visual>
    <origin xyz="-0.003979 -0.061459 -0.02" rpy="0 0 0" />
    <geometry>
      <mesh filename="package://robot_arm_description/meshes/grippers/gripper_a/plate1.stl" scale="0.001 0.001 0.001" />
    </geometry>
    <material name="silver" />
  </visual>
  <collision>
    <origin xyz="-0.003979 -0.061459 -0.02" rpy="0 0 0" />
    <geometry>
      <mesh filename="package://robot_arm_description/meshes/grippers/gripper_a/plate1.stl" scale="0.001 0.001 0.001" />
    </geometry>
  </collision>
</link>


<link name="gripper_a_link5_2">
  <inertial>
    <origin xyz="0.016772882317493503 -0.00818693116986946 -0.0050000000000001285" rpy="0 0 0" />
    <mass value="0.050250119706585376" />
    <inertia ixx="4e-06" iyy="1.2e-05" izz="1.5e-05" ixy="6e-06" iyz="-0.0" ixz="-0.0" />
  </inertial>
  <visual>
    <origin xyz="-0.011511 -0.213329 0.0" rpy="0 0 0" />
    <geometry>
      <mesh filename="package://robot_arm_description/meshes/grippers/gripper_a/link5_2.stl" scale="0.001 0.001 0.001" />
    </geometry>
    <material name="silver" />
  </visual>
  <collision>
    <origin xyz="-0.011511 -0.213329 0.0" rpy="0 0 0" />
    <geometry>
      <mesh filename="package://robot_arm_description/meshes/grippers/gripper_a/link5_2.stl" scale="0.001 0.001 0.001" />
    </geometry>
  </collision>
</link>


<link name="gripper_a_component53_1">
  <inertial>
    <origin xyz="0.016772418745480168 0.008186864045702721 -0.004999999998866036" rpy="0 0 0" />
    <mass value="0.0502501192354395" />
    <inertia ixx="4e-06" iyy="1.2e-05" izz="1.5e-05" ixy="-6e-06" iyz="-0.0" ixz="-0.0" />
  </inertial>
  <visual>
    <origin xyz="0.00251 -0.068983 0.0" rpy="0 0 0" />
    <geometry>
      <mesh filename="package://robot_arm_description/meshes/grippers/gripper_a/component53_1.stl" scale="0.001 0.001 0.001" />
    </geometry>
    <material name="silver" />
  </visual>
  <collision>
    <origin xyz="0.00251 -0.068983 0.0" rpy="0 0 0" />
    <geometry>
      <mesh filename="package://robot_arm_description/meshes/grippers/gripper_a/component53_1.stl" scale="0.001 0.001 0.001" />
    </geometry>
  </collision>
</link>


<link name="gripper_a_Spur_Gear_36_teeth_1">
  <inertial>
    <origin xyz="-3.2714716231840857e-07 -4.718577417683889e-08 0.004999999999850697" rpy="0 0 0" />
    <mass value="0.07732730680958116" />
    <inertia ixx="7e-06" iyy="7e-06" izz="1.3e-05" ixy="-0.0" iyz="-0.0" ixz="-0.0" />
  </inertial>
  <visual>
    <origin xyz="0.038971 -0.164837 -0.01" rpy="0 0 0" />
    <geometry>
      <mesh filename="package://robot_arm_description/meshes/grippers/gripper_a/Spur_Gear_36_teeth_1.stl" scale="0.001 0.001 0.001" />
    </geometry>
    <material name="silver" />
  </visual>
  <collision>
    <origin xyz="0.038971 -0.164837 -0.01" rpy="0 0 0" />
    <geometry>
      <mesh filename="package://robot_arm_description/meshes/grippers/gripper_a/Spur_Gear_36_teeth_1.stl" scale="0.001 0.001 0.001" />
    </geometry>
  </collision>
</link>


<link name="gripper_a_Spur_Gear_36_teeth__1__1">
  <inertial>
    <origin xyz="-3.2694216475087634e-07 -5.104868550098729e-08 0.004999999999850752" rpy="0 0 0" />
    <mass value="0.07732730680957652" />
    <inertia ixx="7e-06" iyy="7e-06" izz="1.3e-05" ixy="-0.0" iyz="0.0" ixz="-0.0" />
  </inertial>
  <visual>
    <origin xyz="0.038971 -0.128737 -0.01" rpy="0 0 0" />
    <geometry>
      <mesh filename="package://robot_arm_description/meshes/grippers/gripper_a/Spur_Gear_36_teeth__1__1.stl" scale="0.001 0.001 0.001" />
    </geometry>
    <material name="silver" />
  </visual>
  <collision>
    <origin xyz="0.038971 -0.128737 -0.01" rpy="0 0 0" />
    <geometry>
      <mesh filename="package://robot_arm_description/meshes/grippers/gripper_a/Spur_Gear_36_teeth__1__1.stl" scale="0.001 0.001 0.001" />
    </geometry>
  </collision>
</link>


<link name="gripper_a_Spur_Gear_24_teeth__2__1">
  <inertial>
    <origin xyz="-7.93697714496222e-09 3.0987010735117337e-09 0.004999999999210494" rpy="0 0 0" />
    <mass value="0.03267478605457942" />
    <inertia ixx="2e-06" iyy="2e-06" izz="3e-06" ixy="0.0" iyz="0.0" ixz="0.0" />
  </inertial>
  <visual>
    <origin xyz="0.068 -0.161 -0.01" rpy="0 0 0" />
    <geometry>
      <mesh filename="package://robot_arm_description/meshes/grippers/gripper_a/Spur_Gear_24_teeth__2__1.stl" scale="0.001 0.001 0.001" />
    </geometry>
    <material name="silver" />
  </visual>
  <collision>
    <origin xyz="0.068 -0.161 -0.01" rpy="0 0 0" />
    <geometry>
      <mesh filename="package://robot_arm_description/meshes/grippers/gripper_a/Spur_Gear_24_teeth__2__1.stl" scale="0.001 0.001 0.001" />
    </geometry>
  </collision>
</link>


<link name="gripper_a_motor_adapter">
  <inertial>
    <origin xyz="-1.013170242147865e-09 2.399086901361258e-09 0.004944029318102771" rpy="0 0 0" />
    <mass value="0.020408786210083112" />
    <inertia ixx="1e-06" iyy="1e-06" izz="1e-06" ixy="0.0" iyz="0.0" ixz="-0.0" />
  </inertial>
  <visual>
    <origin xyz="0.068 -0.161 -0.0" rpy="0 0 0" />
    <geometry>
      <mesh filename="package://robot_arm_description/meshes/grippers/gripper_a/motor_adapter.stl" scale="0.001 0.001 0.001" />
    </geometry>
    <material name="silver" />
  </visual>
  <collision>
    <origin xyz="0.068 -0.161 -0.0" rpy="0 0 0" />
    <geometry>
      <mesh filename="package://robot_arm_description/meshes/grippers/gripper_a/motor_adapter.stl" scale="0.001 0.001 0.001" />
    </geometry>
  </collision>
</link>


<link name="gripper_a_top_plate">
  <inertial>
    <origin xyz="0.017426995133512174 -5.1303759518450676e-08 0.02155194345598499" rpy="0 0 0" />
    <mass value="0.4820949144390761" />
    <inertia ixx="0.00016" iyy="0.000149" izz="0.000203" ixy="0.0" iyz="-0.0" ixz="-2.3e-05" />
  </inertial>
  <visual>
    <origin xyz="0.052321 -0.146787 0.036" rpy="0 0 0" />
    <geometry>
      <mesh filename="package://robot_arm_description/meshes/grippers/gripper_a/top_plate.stl" scale="0.001 0.001 0.001" />
    </geometry>
    <material name="silver" />
  </visual>
  <collision>
    <origin xyz="0.052321 -0.146787 0.036" rpy="0 0 0" />
    <geometry>
      <mesh filename="package://robot_arm_description/meshes/grippers/gripper_a/top_plate.stl" scale="0.001 0.001 0.001" />
    </geometry>
  </collision>
</link>


<joint name="gripper_a_joint5" type="continuous">
  <origin xyz="0.01335 0.01805 0.036" rpy="0 0 0" />
  <parent link="gripper_a_top_plate" />
  <child link="gripper_a_link1" />
  <axis xyz="-0.0 0.0 -1.0" />
</joint>


<joint name="gripper_a_joint6" type="continuous">
  <origin xyz="0.01335 -0.01805 0.036" rpy="0 0 0" />
  <parent link="gripper_a_top_plate" />
  <child link="gripper_a_link3" />
  <axis xyz="-0.0 0.0 -1.0" />
</joint>


<joint name="gripper_a_joint7" type="continuous">
  <origin xyz="0.038228 0.008 0.036" rpy="0 0 0" />
  <parent link="gripper_a_top_plate" />
  <child link="gripper_a_link2" />
  <axis xyz="-0.0 0.0 -1.0" />
</joint>


<joint name="gripper_a_joint8" type="continuous">
  <origin xyz="0.038228 -0.008 0.036" rpy="0 0 0" />
  <parent link="gripper_a_top_plate" />
  <child link="gripper_a_link4" />
  <axis xyz="-0.0 0.0 -1.0" />
</joint>


<joint name="gripper_a_joint9" type="continuous">
  <origin xyz="0.053456 0.053654 0.01" rpy="0 0 0" />
  <parent link="gripper_a_link1" />
  <child link="gripper_a_link5" />
  <axis xyz="-0.0 0.0 -1.0" />
</joint>


<joint name="gripper_a_joint11" type="continuous">
  <origin xyz="0.061339 -0.049705 0.01" rpy="0 0 0" />
  <parent link="gripper_a_link3" />
  <child link="gripper_a_link6" />
  <axis xyz="-0.0 0.0 -1.0" />
</joint>


<joint name="gripper_a_fixed15" type="fixed">
  <origin xyz="0.016119 -0.008895 0.009" rpy="0 0 0" />
  <parent link="gripper_a_link5" />
  <child link="gripper_a_plate2" />
</joint>


<joint name="gripper_a_fixed16" type="fixed">
  <origin xyz="-0.018389 -0.017573 0.01" rpy="0 0 0" />
  <parent link="gripper_a_link6" />
  <child link="gripper_a_plate1" />
</joint>


<joint name="gripper_a_joint17" type="continuous">
  <origin xyz="0.053456 0.053654 0.0" rpy="0 0 0" />
  <parent link="gripper_a_link1" />
  <child link="gripper_a_link5_2" />
  <axis xyz="0.0 0.0 1.0" />
</joint>


<joint name="gripper_a_joint19" type="continuous">
  <origin xyz="0.061339 -0.049705 0.0" rpy="0 0 0" />
  <parent link="gripper_a_link3" />
  <child link="gripper_a_component53_1" />
  <axis xyz="0.0 -0.0 1.0" />
</joint>


<joint name="gripper_a_joint21" type="continuous">
  <origin xyz="0.0 0.0 0.01" rpy="0 0 0" />
  <parent link="gripper_a_link1" />
  <child link="gripper_a_Spur_Gear_36_teeth_1" />
  <axis xyz="0.0 0.0 1.0" />
</joint>


<joint name="gripper_a_joint22" type="continuous">
  <origin xyz="0.0 0.0 0.01" rpy="0 0 0" />
  <parent link="gripper_a_link3" />
  <child link="gripper_a_Spur_Gear_36_teeth__1__1" />
  <axis xyz="-0.0 0.0 -1.0" />
</joint>


<joint name="gripper_a_joint23" type="continuous">
  <origin xyz="0.0 0.0 0.01" rpy="0 0 0" />
  <parent link="gripper_a_motor_adapter" />
  <child link="gripper_a_Spur_Gear_24_teeth__2__1" />
  <axis xyz="0.0 -0.0 -1.0" />
</joint>


<joint name="gripper_a_fixed24" type="fixed">
  <origin xyz="-0.068 0.161 0.0" rpy="0 0 0" />
  <parent link="gripper_a_base_link" />
  <child link="gripper_a_motor_adapter" />
</joint>


<joint name="gripper_a_fixed25" type="fixed">
  <origin xyz="-0.052321 0.146787 -0.036" rpy="0 0 0" />
  <parent link="gripper_a_base_link" />
  <child link="gripper_a_top_plate" />
</joint>

</robot>


